Workbook
Name 날짜: 달력!A$6
Name 슬라이서_구분: #N/A
Name 슬라이서_날짜: #N/A
Name 슬라이서_시작일: #N/A
Name 슬라이서_우선순위1: #N/A
Name 슬라이서_월: #N/A
Name 슬라이서_진행상태: #N/A
Name 슬라이서_카테고리: #N/A

Sheet 달력
B6: =UPPER(TEXT(B7,"ddd")) -> SUN | F6: =UPPER(TEXT(F7,"ddd")) -> MON | J6: =UPPER(TEXT(J7,"ddd")) -> TUE | N6: =UPPER(TEXT(N7,"ddd")) -> WED | R6: =UPPER(TEXT(R7,"ddd")) -> THU | V6: =UPPER(TEXT(V7,"ddd")) -> FRI | Z6: =UPPER(TEXT(Z7,"ddd")) -> SAT
B7: =피벗!V3-피벗!W3+IF(피벗!AA3="월요일",2,1) -> 46264 | F7: =B7+1 -> 46265 | J7: =F7+1 -> 46266 | N7: =J7+1 -> 46267 | R7: =N7+1 -> 46268 | V7: =R7+1 -> 46269 | Z7: =V7+1 -> 46270 | AM7: =RAND() -> 0.8810188
B8: {=IFERROR(IF(COUNTIFS(할일표[날짜],B$7,할일표[업무],"<>")<1,"",INDEX(구분표[아이콘],MATCH(INDEX(할일표[구분],SMALL(IF((할일표[날짜]=B$7)*(할일표[업무]<>""),ROW(할일표[구분])-ROW(INDEX(할일표[구분],1))+1),1)),구분표[구분],0))),"")} | C8: {=IFERROR(IF(COUNTIFS(할일표[날짜],B$7,할일표[업무],"<>")<1,"",INDEX(할일표[표시],SMALL(IF((할일표[날짜]=B$7)*(할일표[업무]<>""),ROW(할일표[표시])-ROW(INDEX(할일표[표시],1))+1),1))),"")} | D8: {=IFERROR(IF(COUNTIFS(할일표[날짜],B$7,할일표[업무],"<>")<1,"",INDEX(할일표[업무],SMALL(IF((할일표[날짜]=B$7)*(할일표[업무]<>""),ROW(할일표[날짜])-피벗!$T$11),1))),"")} | E8: {=IFERROR(IF(COUNTIFS(할일표[날짜],B$7,할일표[업무],"<>")<1,"",INDEX(할일표[진행률],SMALL(IF((할일표[날짜]=B$7)*(할일표[업무]<>""),ROW(할일표[날짜])-피벗!$T$11),1))),"")} | F8: {=IFERROR(IF(COUNTIFS(할일표[날짜],F$7,할일표[업무],"<>")<1,"",INDEX(구분표[아이콘],MATCH(INDEX(할일표[구분],SMALL(IF((할일표[날짜]=F$7)*(할일표[업무]<>""),ROW(할일표[구분])-ROW(INDEX(할일표[구분],1))+1),1)),구분표[구분],0))),"")} | G8: {=IFERROR(IF(COUNTIFS(할일표[날짜],F$7,할일표[업무],"<>")<1,"",INDEX(할일표[표시],SMALL(IF((할일표[날짜]=F$7)*(할일표[업무]<>""),ROW(할일표[표시])-ROW(INDEX(할일표[표시],1))+1),1))),"")} | H8: {=IFERROR(IF(COUNTIFS(할일표[날짜],F$7,할일표[업무],"<>")<1,"",INDEX(할일표[업무],SMALL(IF((할일표[날짜]=F$7)*(할일표[업무]<>""),ROW(할일표[날짜])-피벗!$T$11),1))),"")} | I8: {=IFERROR(IF(COUNTIFS(할일표[날짜],F$7,할일표[업무],"<>")<1,"",INDEX(할일표[진행률],SMALL(IF((할일표[날짜]=F$7)*(할일표[업무]<>""),ROW(할일표[날짜])-피벗!$T$11),1))),"")} | J8: {=IFERROR(IF(COUNTIFS(할일표[날짜],J$7,할일표[업무],"<>")<1,"",INDEX(구분표[아이콘],MATCH(INDEX(할일표[구분],SMALL(IF((할일표[날짜]=J$7)*(할일표[업무]<>""),ROW(할일표[구분])-ROW(INDEX(할일표[구분],1))+1),1)),구분표[구분],0))),"")} | K8: {=IFERROR(IF(COUNTIFS(할일표[날짜],J$7,할일표[업무],"<>")<1,"",INDEX(할일표[표시],SMALL(IF((할일표[날짜]=J$7)*(할일표[업무]<>""),ROW(할일표[표시])-ROW(INDEX(할일표[표시],1))+1),1))),"")} | L8: {=IFERROR(IF(COUNTIFS(할일표[날짜],J$7,할일표[업무],"<>")<1,"",INDEX(할일표[업무],SMALL(IF((할일표[날짜]=J$7)*(할일표[업무]<>""),ROW(할일표[날짜])-피벗!$T$11),1))),"")} | M8: {=IFERROR(IF(COUNTIFS(할일표[날짜],J$7,할일표[업무],"<>")<1,"",INDEX(할일표[진행률],SMALL(IF((할일표[날짜]=J$7)*(할일표[업무]<>""),ROW(할일표[날짜])-피벗!$T$11),1))),"")} | N8: {=IFERROR(IF(COUNTIFS(할일표[날짜],N$7,할일표[업무],"<>")<1,"",INDEX(구분표[아이콘],MATCH(INDEX(할일표[구분],SMALL(IF((할일표[날짜]=N$7)*(할일표[업무]<>""),ROW(할일표[구분])-ROW(INDEX(할일표[구분],1))+1),1)),구분표[구분],0))),"")} | O8: {=IFERROR(IF(COUNTIFS(할일표[날짜],N$7,할일표[업무],"<>")<1,"",INDEX(할일표[표시],SMALL(IF((할일표[날짜]=N$7)*(할일표[업무]<>""),ROW(할일표[표시])-ROW(INDEX(할일표[표시],1))+1),1))),"")} | P8: {=IFERROR(IF(COUNTIFS(할일표[날짜],N$7,할일표[업무],"<>")<1,"",INDEX(할일표[업무],SMALL(IF((할일표[날짜]=N$7)*(할일표[업무]<>""),ROW(할일표[날짜])-피벗!$T$11),1))),"")} | Q8: {=IFERROR(IF(COUNTIFS(할일표[날짜],N$7,할일표[업무],"<>")<1,"",INDEX(할일표[진행률],SMALL(IF((할일표[날짜]=N$7)*(할일표[업무]<>""),ROW(할일표[날짜])-피벗!$T$11),1))),"")} | R8: {=IFERROR(IF(COUNTIFS(할일표[날짜],R$7,할일표[업무],"<>")<1,"",INDEX(구분표[아이콘],MATCH(INDEX(할일표[구분],SMALL(IF((할일표[날짜]=R$7)*(할일표[업무]<>""),ROW(할일표[구분])-ROW(INDEX(할일표[구분],1))+1),1)),구분표[구분],0))),"")} | S8: {=IFERROR(IF(COUNTIFS(할일표[날짜],R$7,할일표[업무],"<>")<1,"",INDEX(할일표[표시],SMALL(IF((할일표[날짜]=R$7)*(할일표[업무]<>""),ROW(할일표[표시])-ROW(INDEX(할일표[표시],1))+1),1))),"")} | T8: {=IFERROR(IF(COUNTIFS(할일표[날짜],R$7,할일표[업무],"<>")<1,"",INDEX(할일표[업무],SMALL(IF((할일표[날짜]=R$7)*(할일표[업무]<>""),ROW(할일표[날짜])-피벗!$T$11),1))),"")} | U8: {=IFERROR(IF(COUNTIFS(할일표[날짜],R$7,할일표[업무],"<>")<1,"",INDEX(할일표[진행률],SMALL(IF((할일표[날짜]=R$7)*(할일표[업무]<>""),ROW(할일표[날짜])-피벗!$T$11),1))),"")} | V8: {=IFERROR(IF(COUNTIFS(할일표[날짜],V$7,할일표[업무],"<>")<1,"",INDEX(구분표[아이콘],MATCH(INDEX(할일표[구분],SMALL(IF((할일표[날짜]=V$7)*(할일표[업무]<>""),ROW(할일표[구분])-ROW(INDEX(할일표[구분],1))+1),1)),구분표[구분],0))),"")} | W8: {=IFERROR(IF(COUNTIFS(할일표[날짜],V$7,할일표[업무],"<>")<1,"",INDEX(할일표[표시],SMALL(IF((할일표[날짜]=V$7)*(할일표[업무]<>""),ROW(할일표[표시])-ROW(INDEX(할일표[표시],1))+1),1))),"")} | X8: {=IFERROR(IF(COUNTIFS(할일표[날짜],V$7,할일표[업무],"<>")<1,"",INDEX(할일표[업무],SMALL(IF((할일표[날짜]=V$7)*(할일표[업무]<>""),ROW(할일표[날짜])-피벗!$T$11),1))),"")} | Y8: {=IFERROR(IF(COUNTIFS(할일표[날짜],V$7,할일표[업무],"<>")<1,"",INDEX(할일표[진행률],SMALL(IF((할일표[날짜]=V$7)*(할일표[업무]<>""),ROW(할일표[날짜])-피벗!$T$11),1))),"")} | Z8: {=IFERROR(IF(COUNTIFS(할일표[날짜],Z$7,할일표[업무],"<>")<1,"",INDEX(구분표[아이콘],MATCH(INDEX(할일표[구분],SMALL(IF((할일표[날짜]=Z$7)*(할일표[업무]<>""),ROW(할일표[구분])-ROW(INDEX(할일표[구분],1))+1),1)),구분표[구분],0))),"")} | AA8: {=IFERROR(IF(COUNTIFS(할일표[날짜],Z$7,할일표[업무],"<>")<1,"",INDEX(할일표[표시],SMALL(IF((할일표[날짜]=Z$7)*(할일표[업무]<>""),ROW(할일표[표시])-ROW(INDEX(할일표[표시],1))+1),1))),"")} | AB8: {=IFERROR(IF(COUNTIFS(할일표[날짜],Z$7,할일표[업무],"<>")<1,"",INDEX(할일표[업무],SMALL(IF((할일표[날짜]=Z$7)*(할일표[업무]<>""),ROW(할일표[날짜])-피벗!$T$11),1))),"")} | AC8: {=IFERROR(IF(COUNTIFS(할일표[날짜],Z$7,할일표[업무],"<>")<1,"",INDEX(할일표[진행률],SMALL(IF((할일표[날짜]=Z$7)*(할일표[업무]<>""),ROW(할일표[날짜])-피벗!$T$11),1))),"")} | AL8: =RAND() -> 0.15094835 | AM8: =RAND() -> 0.25580972 | AN8: =RAND() -> 0.52156365
B9: {=IFERROR(IF(COUNTIFS(할일표[날짜],B$7,할일표[업무],"<>")<2,"",INDEX(구분표[아이콘],MATCH(INDEX(할일표[구분],SMALL(IF((할일표[날짜]=B$7)*(할일표[업무]<>""),ROW(할일표[구분])-ROW(INDEX(할일표[구분],1))+1),2)),구분표[구분],0))),"")} | C9: {=IFERROR(IF(COUNTIFS(할일표[날짜],B$7,할일표[업무],"<>")<2,"",INDEX(할일표[표시],SMALL(IF((할일표[날짜]=B$7)*(할일표[업무]<>""),ROW(할일표[표시])-ROW(INDEX(할일표[표시],1))+1),2))),"")} | D9: {=IFERROR(IF(COUNTIFS(할일표[날짜],B$7,할일표[업무],"<>")<2,"",INDEX(할일표[업무],SMALL(IF((할일표[날짜]=B$7)*(할일표[업무]<>""),ROW(할일표[날짜])-피벗!$T$11),2))),"")} | E9: {=IFERROR(IF(COUNTIFS(할일표[날짜],B$7,할일표[업무],"<>")<2,"",INDEX(할일표[진행률],SMALL(IF((할일표[날짜]=B$7)*(할일표[업무]<>""),ROW(할일표[날짜])-피벗!$T$11),2))),"")} | F9: {=IFERROR(IF(COUNTIFS(할일표[날짜],F$7,할일표[업무],"<>")<2,"",INDEX(구분표[아이콘],MATCH(INDEX(할일표[구분],SMALL(IF((할일표[날짜]=F$7)*(할일표[업무]<>""),ROW(할일표[구분])-ROW(INDEX(할일표[구분],1))+1),2)),구분표[구분],0))),"")} | G9: {=IFERROR(IF(COUNTIFS(할일표[날짜],F$7,할일표[업무],"<>")<2,"",INDEX(할일표[표시],SMALL(IF((할일표[날짜]=F$7)*(할일표[업무]<>""),ROW(할일표[표시])-ROW(INDEX(할일표[표시],1))+1),2))),"")} | H9: {=IFERROR(IF(COUNTIFS(할일표[날짜],F$7,할일표[업무],"<>")<2,"",INDEX(할일표[업무],SMALL(IF((할일표[날짜]=F$7)*(할일표[업무]<>""),ROW(할일표[날짜])-피벗!$T$11),2))),"")} | I9: {=IFERROR(IF(COUNTIFS(할일표[날짜],F$7,할일표[업무],"<>")<2,"",INDEX(할일표[진행률],SMALL(IF((할일표[날짜]=F$7)*(할일표[업무]<>""),ROW(할일표[날짜])-피벗!$T$11),2))),"")} | J9: {=IFERROR(IF(COUNTIFS(할일표[날짜],J$7,할일표[업무],"<>")<2,"",INDEX(구분표[아이콘],MATCH(INDEX(할일표[구분],SMALL(IF((할일표[날짜]=J$7)*(할일표[업무]<>""),ROW(할일표[구분])-ROW(INDEX(할일표[구분],1))+1),2)),구분표[구분],0))),"")} | K9: {=IFERROR(IF(COUNTIFS(할일표[날짜],J$7,할일표[업무],"<>")<2,"",INDEX(할일표[표시],SMALL(IF((할일표[날짜]=J$7)*(할일표[업무]<>""),ROW(할일표[표시])-ROW(INDEX(할일표[표시],1))+1),2))),"")} | L9: {=IFERROR(IF(COUNTIFS(할일표[날짜],J$7,할일표[업무],"<>")<2,"",INDEX(할일표[업무],SMALL(IF((할일표[날짜]=J$7)*(할일표[업무]<>""),ROW(할일표[날짜])-피벗!$T$11),2))),"")} | M9: {=IFERROR(IF(COUNTIFS(할일표[날짜],J$7,할일표[업무],"<>")<2,"",INDEX(할일표[진행률],SMALL(IF((할일표[날짜]=J$7)*(할일표[업무]<>""),ROW(할일표[날짜])-피벗!$T$11),2))),"")} | N9: {=IFERROR(IF(COUNTIFS(할일표[날짜],N$7,할일표[업무],"<>")<2,"",INDEX(구분표[아이콘],MATCH(INDEX(할일표[구분],SMALL(IF((할일표[날짜]=N$7)*(할일표[업무]<>""),ROW(할일표[구분])-ROW(INDEX(할일표[구분],1))+1),2)),구분표[구분],0))),"")} | O9: {=IFERROR(IF(COUNTIFS(할일표[날짜],N$7,할일표[업무],"<>")<2,"",INDEX(할일표[표시],SMALL(IF((할일표[날짜]=N$7)*(할일표[업무]<>""),ROW(할일표[표시])-ROW(INDEX(할일표[표시],1))+1),2))),"")} | P9: {=IFERROR(IF(COUNTIFS(할일표[날짜],N$7,할일표[업무],"<>")<2,"",INDEX(할일표[업무],SMALL(IF((할일표[날짜]=N$7)*(할일표[업무]<>""),ROW(할일표[날짜])-피벗!$T$11),2))),"")} | Q9: {=IFERROR(IF(COUNTIFS(할일표[날짜],N$7,할일표[업무],"<>")<2,"",INDEX(할일표[진행률],SMALL(IF((할일표[날짜]=N$7)*(할일표[업무]<>""),ROW(할일표[날짜])-피벗!$T$11),2))),"")} | R9: {=IFERROR(IF(COUNTIFS(할일표[날짜],R$7,할일표[업무],"<>")<2,"",INDEX(구분표[아이콘],MATCH(INDEX(할일표[구분],SMALL(IF((할일표[날짜]=R$7)*(할일표[업무]<>""),ROW(할일표[구분])-ROW(INDEX(할일표[구분],1))+1),2)),구분표[구분],0))),"")} | S9: {=IFERROR(IF(COUNTIFS(할일표[날짜],R$7,할일표[업무],"<>")<2,"",INDEX(할일표[표시],SMALL(IF((할일표[날짜]=R$7)*(할일표[업무]<>""),ROW(할일표[표시])-ROW(INDEX(할일표[표시],1))+1),2))),"")} | T9: {=IFERROR(IF(COUNTIFS(할일표[날짜],R$7,할일표[업무],"<>")<2,"",INDEX(할일표[업무],SMALL(IF((할일표[날짜]=R$7)*(할일표[업무]<>""),ROW(할일표[날짜])-피벗!$T$11),2))),"")} | U9: {=IFERROR(IF(COUNTIFS(할일표[날짜],R$7,할일표[업무],"<>")<2,"",INDEX(할일표[진행률],SMALL(IF((할일표[날짜]=R$7)*(할일표[업무]<>""),ROW(할일표[날짜])-피벗!$T$11),2))),"")} | V9: {=IFERROR(IF(COUNTIFS(할일표[날짜],V$7,할일표[업무],"<>")<2,"",INDEX(구분표[아이콘],MATCH(INDEX(할일표[구분],SMALL(IF((할일표[날짜]=V$7)*(할일표[업무]<>""),ROW(할일표[구분])-ROW(INDEX(할일표[구분],1))+1),2)),구분표[구분],0))),"")} | W9: {=IFERROR(IF(COUNTIFS(할일표[날짜],V$7,할일표[업무],"<>")<2,"",INDEX(할일표[표시],SMALL(IF((할일표[날짜]=V$7)*(할일표[업무]<>""),ROW(할일표[표시])-ROW(INDEX(할일표[표시],1))+1),2))),"")} | X9: {=IFERROR(IF(COUNTIFS(할일표[날짜],V$7,할일표[업무],"<>")<2,"",INDEX(할일표[업무],SMALL(IF((할일표[날짜]=V$7)*(할일표[업무]<>""),ROW(할일표[날짜])-피벗!$T$11),2))),"")} | Y9: {=IFERROR(IF(COUNTIFS(할일표[날짜],V$7,할일표[업무],"<>")<2,"",INDEX(할일표[진행률],SMALL(IF((할일표[날짜]=V$7)*(할일표[업무]<>""),ROW(할일표[날짜])-피벗!$T$11),2))),"")} | Z9: {=IFERROR(IF(COUNTIFS(할일표[날짜],Z$7,할일표[업무],"<>")<2,"",INDEX(구분표[아이콘],MATCH(INDEX(할일표[구분],SMALL(IF((할일표[날짜]=Z$7)*(할일표[업무]<>""),ROW(할일표[구분])-ROW(INDEX(할일표[구분],1))+1),2)),구분표[구분],0))),"")} | AA9: {=IFERROR(IF(COUNTIFS(할일표[날짜],Z$7,할일표[업무],"<>")<2,"",INDEX(할일표[표시],SMALL(IF((할일표[날짜]=Z$7)*(할일표[업무]<>""),ROW(할일표[표시])-ROW(INDEX(할일표[표시],1))+1),2))),"")} | AB9: {=IFERROR(IF(COUNTIFS(할일표[날짜],Z$7,할일표[업무],"<>")<2,"",INDEX(할일표[업무],SMALL(IF((할일표[날짜]=Z$7)*(할일표[업무]<>""),ROW(할일표[날짜])-피벗!$T$11),2))),"")} | AC9: {=IFERROR(IF(COUNTIFS(할일표[날짜],Z$7,할일표[업무],"<>")<2,"",INDEX(할일표[진행률],SMALL(IF((할일표[날짜]=Z$7)*(할일표[업무]<>""),ROW(할일표[날짜])-피벗!$T$11),2))),"")} | AL9: =RAND() -> 0.68862111 | AM9: =RAND() -> 0.081890282 | AN9: =RAND() -> 0.58658144
B10: {=IFERROR(IF(COUNTIFS(할일표[날짜],B$7,할일표[업무],"<>")<3,"",INDEX(구분표[아이콘],MATCH(INDEX(할일표[구분],SMALL(IF((할일표[날짜]=B$7)*(할일표[업무]<>""),ROW(할일표[구분])-ROW(INDEX(할일표[구분],1))+1),3)),구분표[구분],0))),"")} | C10: {=IFERROR(IF(COUNTIFS(할일표[날짜],B$7,할일표[업무],"<>")<3,"",INDEX(할일표[표시],SMALL(IF((할일표[날짜]=B$7)*(할일표[업무]<>""),ROW(할일표[표시])-ROW(INDEX(할일표[표시],1))+1),3))),"")} | D10: {=IFERROR(IF(COUNTIFS(할일표[날짜],B$7,할일표[업무],"<>")<3,"",INDEX(할일표[업무],SMALL(IF((할일표[날짜]=B$7)*(할일표[업무]<>""),ROW(할일표[날짜])-피벗!$T$11),3))),"")} | E10: {=IFERROR(IF(COUNTIFS(할일표[날짜],B$7,할일표[업무],"<>")<3,"",INDEX(할일표[진행률],SMALL(IF((할일표[날짜]=B$7)*(할일표[업무]<>""),ROW(할일표[날짜])-피벗!$T$11),3))),"")} | F10: {=IFERROR(IF(COUNTIFS(할일표[날짜],F$7,할일표[업무],"<>")<3,"",INDEX(구분표[아이콘],MATCH(INDEX(할일표[구분],SMALL(IF((할일표[날짜]=F$7)*(할일표[업무]<>""),ROW(할일표[구분])-ROW(INDEX(할일표[구분],1))+1),3)),구분표[구분],0))),"")} | G10: {=IFERROR(IF(COUNTIFS(할일표[날짜],F$7,할일표[업무],"<>")<3,"",INDEX(할일표[표시],SMALL(IF((할일표[날짜]=F$7)*(할일표[업무]<>""),ROW(할일표[표시])-ROW(INDEX(할일표[표시],1))+1),3))),"")} | H10: {=IFERROR(IF(COUNTIFS(할일표[날짜],F$7,할일표[업무],"<>")<3,"",INDEX(할일표[업무],SMALL(IF((할일표[날짜]=F$7)*(할일표[업무]<>""),ROW(할일표[날짜])-피벗!$T$11),3))),"")} | I10: {=IFERROR(IF(COUNTIFS(할일표[날짜],F$7,할일표[업무],"<>")<3,"",INDEX(할일표[진행률],SMALL(IF((할일표[날짜]=F$7)*(할일표[업무]<>""),ROW(할일표[날짜])-피벗!$T$11),3))),"")} | J10: {=IFERROR(IF(COUNTIFS(할일표[날짜],J$7,할일표[업무],"<>")<3,"",INDEX(구분표[아이콘],MATCH(INDEX(할일표[구분],SMALL(IF((할일표[날짜]=J$7)*(할일표[업무]<>""),ROW(할일표[구분])-ROW(INDEX(할일표[구분],1))+1),3)),구분표[구분],0))),"")} | K10: {=IFERROR(IF(COUNTIFS(할일표[날짜],J$7,할일표[업무],"<>")<3,"",INDEX(할일표[표시],SMALL(IF((할일표[날짜]=J$7)*(할일표[업무]<>""),ROW(할일표[표시])-ROW(INDEX(할일표[표시],1))+1),3))),"")} | L10: {=IFERROR(IF(COUNTIFS(할일표[날짜],J$7,할일표[업무],"<>")<3,"",INDEX(할일표[업무],SMALL(IF((할일표[날짜]=J$7)*(할일표[업무]<>""),ROW(할일표[날짜])-피벗!$T$11),3))),"")} | M10: {=IFERROR(IF(COUNTIFS(할일표[날짜],J$7,할일표[업무],"<>")<3,"",INDEX(할일표[진행률],SMALL(IF((할일표[날짜]=J$7)*(할일표[업무]<>""),ROW(할일표[날짜])-피벗!$T$11),3))),"")} | N10: {=IFERROR(IF(COUNTIFS(할일표[날짜],N$7,할일표[업무],"<>")<3,"",INDEX(구분표[아이콘],MATCH(INDEX(할일표[구분],SMALL(IF((할일표[날짜]=N$7)*(할일표[업무]<>""),ROW(할일표[구분])-ROW(INDEX(할일표[구분],1))+1),3)),구분표[구분],0))),"")} | O10: {=IFERROR(IF(COUNTIFS(할일표[날짜],N$7,할일표[업무],"<>")<3,"",INDEX(할일표[표시],SMALL(IF((할일표[날짜]=N$7)*(할일표[업무]<>""),ROW(할일표[표시])-ROW(INDEX(할일표[표시],1))+1),3))),"")} | P10: {=IFERROR(IF(COUNTIFS(할일표[날짜],N$7,할일표[업무],"<>")<3,"",INDEX(할일표[업무],SMALL(IF((할일표[날짜]=N$7)*(할일표[업무]<>""),ROW(할일표[날짜])-피벗!$T$11),3))),"")} | Q10: {=IFERROR(IF(COUNTIFS(할일표[날짜],N$7,할일표[업무],"<>")<3,"",INDEX(할일표[진행률],SMALL(IF((할일표[날짜]=N$7)*(할일표[업무]<>""),ROW(할일표[날짜])-피벗!$T$11),3))),"")} | R10: {=IFERROR(IF(COUNTIFS(할일표[날짜],R$7,할일표[업무],"<>")<3,"",INDEX(구분표[아이콘],MATCH(INDEX(할일표[구분],SMALL(IF((할일표[날짜]=R$7)*(할일표[업무]<>""),ROW(할일표[구분])-ROW(INDEX(할일표[구분],1))+1),3)),구분표[구분],0))),"")} | S10: {=IFERROR(IF(COUNTIFS(할일표[날짜],R$7,할일표[업무],"<>")<3,"",INDEX(할일표[표시],SMALL(IF((할일표[날짜]=R$7)*(할일표[업무]<>""),ROW(할일표[표시])-ROW(INDEX(할일표[표시],1))+1),3))),"")} | T10: {=IFERROR(IF(COUNTIFS(할일표[날짜],R$7,할일표[업무],"<>")<3,"",INDEX(할일표[업무],SMALL(IF((할일표[날짜]=R$7)*(할일표[업무]<>""),ROW(할일표[날짜])-피벗!$T$11),3))),"")} | U10: {=IFERROR(IF(COUNTIFS(할일표[날짜],R$7,할일표[업무],"<>")<3,"",INDEX(할일표[진행률],SMALL(IF((할일표[날짜]=R$7)*(할일표[업무]<>""),ROW(할일표[날짜])-피벗!$T$11),3))),"")} | V10: {=IFERROR(IF(COUNTIFS(할일표[날짜],V$7,할일표[업무],"<>")<3,"",INDEX(구분표[아이콘],MATCH(INDEX(할일표[구분],SMALL(IF((할일표[날짜]=V$7)*(할일표[업무]<>""),ROW(할일표[구분])-ROW(INDEX(할일표[구분],1))+1),3)),구분표[구분],0))),"")} | W10: {=IFERROR(IF(COUNTIFS(할일표[날짜],V$7,할일표[업무],"<>")<3,"",INDEX(할일표[표시],SMALL(IF((할일표[날짜]=V$7)*(할일표[업무]<>""),ROW(할일표[표시])-ROW(INDEX(할일표[표시],1))+1),3))),"")} | X10: {=IFERROR(IF(COUNTIFS(할일표[날짜],V$7,할일표[업무],"<>")<3,"",INDEX(할일표[업무],SMALL(IF((할일표[날짜]=V$7)*(할일표[업무]<>""),ROW(할일표[날짜])-피벗!$T$11),3))),"")} | Y10: {=IFERROR(IF(COUNTIFS(할일표[날짜],V$7,할일표[업무],"<>")<3,"",INDEX(할일표[진행률],SMALL(IF((할일표[날짜]=V$7)*(할일표[업무]<>""),ROW(할일표[날짜])-피벗!$T$11),3))),"")} | Z10: {=IFERROR(IF(COUNTIFS(할일표[날짜],Z$7,할일표[업무],"<>")<3,"",INDEX(구분표[아이콘],MATCH(INDEX(할일표[구분],SMALL(IF((할일표[날짜]=Z$7)*(할일표[업무]<>""),ROW(할일표[구분])-ROW(INDEX(할일표[구분],1))+1),3)),구분표[구분],0))),"")} | AA10: {=IFERROR(IF(COUNTIFS(할일표[날짜],Z$7,할일표[업무],"<>")<3,"",INDEX(할일표[표시],SMALL(IF((할일표[날짜]=Z$7)*(할일표[업무]<>""),ROW(할일표[표시])-ROW(INDEX(할일표[표시],1))+1),3))),"")} | AB10: {=IFERROR(IF(COUNTIFS(할일표[날짜],Z$7,할일표[업무],"<>")<3,"",INDEX(할일표[업무],SMALL(IF((할일표[날짜]=Z$7)*(할일표[업무]<>""),ROW(할일표[날짜])-피벗!$T$11),3))),"")} | AC10: {=IFERROR(IF(COUNTIFS(할일표[날짜],Z$7,할일표[업무],"<>")<3,"",INDEX(할일표[진행률],SMALL(IF((할일표[날짜]=Z$7)*(할일표[업무]<>""),ROW(할일표[날짜])-피벗!$T$11),3))),"")} | AK10: =RAND() -> 0.83110692 | AL10: =RAND() -> 0.091095997 | AM10: =RAND() -> 0.63991662 | AN10: =RAND() -> 0.88203592 | AO10: =RAND() -> 0.58838301
B11: {=IFERROR(IF(COUNTIFS(할일표[날짜],B$7,할일표[업무],"<>")<4,"",INDEX(구분표[아이콘],MATCH(INDEX(할일표[구분],SMALL(IF((할일표[날짜]=B$7)*(할일표[업무]<>""),ROW(할일표[구분])-ROW(INDEX(할일표[구분],1))+1),4)),구분표[구분],0))),"")} | C11: {=IFERROR(IF(COUNTIFS(할일표[날짜],B$7,할일표[업무],"<>")<4,"",INDEX(할일표[표시],SMALL(IF((할일표[날짜]=B$7)*(할일표[업무]<>""),ROW(할일표[표시])-ROW(INDEX(할일표[표시],1))+1),4))),"")} | D11: {=IFERROR(IF(COUNTIFS(할일표[날짜],B$7,할일표[업무],"<>")<4,"",INDEX(할일표[업무],SMALL(IF((할일표[날짜]=B$7)*(할일표[업무]<>""),ROW(할일표[날짜])-피벗!$T$11),4))),"")} | E11: {=IFERROR(IF(COUNTIFS(할일표[날짜],B$7,할일표[업무],"<>")<4,"",INDEX(할일표[진행률],SMALL(IF((할일표[날짜]=B$7)*(할일표[업무]<>""),ROW(할일표[날짜])-피벗!$T$11),4))),"")} | F11: {=IFERROR(IF(COUNTIFS(할일표[날짜],F$7,할일표[업무],"<>")<4,"",INDEX(구분표[아이콘],MATCH(INDEX(할일표[구분],SMALL(IF((할일표[날짜]=F$7)*(할일표[업무]<>""),ROW(할일표[구분])-ROW(INDEX(할일표[구분],1))+1),4)),구분표[구분],0))),"")} | G11: {=IFERROR(IF(COUNTIFS(할일표[날짜],F$7,할일표[업무],"<>")<4,"",INDEX(할일표[표시],SMALL(IF((할일표[날짜]=F$7)*(할일표[업무]<>""),ROW(할일표[표시])-ROW(INDEX(할일표[표시],1))+1),4))),"")} | H11: {=IFERROR(IF(COUNTIFS(할일표[날짜],F$7,할일표[업무],"<>")<4,"",INDEX(할일표[업무],SMALL(IF((할일표[날짜]=F$7)*(할일표[업무]<>""),ROW(할일표[날짜])-피벗!$T$11),4))),"")} | I11: {=IFERROR(IF(COUNTIFS(할일표[날짜],F$7,할일표[업무],"<>")<4,"",INDEX(할일표[진행률],SMALL(IF((할일표[날짜]=F$7)*(할일표[업무]<>""),ROW(할일표[날짜])-피벗!$T$11),4))),"")} | J11: {=IFERROR(IF(COUNTIFS(할일표[날짜],J$7,할일표[업무],"<>")<4,"",INDEX(구분표[아이콘],MATCH(INDEX(할일표[구분],SMALL(IF((할일표[날짜]=J$7)*(할일표[업무]<>""),ROW(할일표[구분])-ROW(INDEX(할일표[구분],1))+1),4)),구분표[구분],0))),"")} | K11: {=IFERROR(IF(COUNTIFS(할일표[날짜],J$7,할일표[업무],"<>")<4,"",INDEX(할일표[표시],SMALL(IF((할일표[날짜]=J$7)*(할일표[업무]<>""),ROW(할일표[표시])-ROW(INDEX(할일표[표시],1))+1),4))),"")} | L11: {=IFERROR(IF(COUNTIFS(할일표[날짜],J$7,할일표[업무],"<>")<4,"",INDEX(할일표[업무],SMALL(IF((할일표[날짜]=J$7)*(할일표[업무]<>""),ROW(할일표[날짜])-피벗!$T$11),4))),"")} | M11: {=IFERROR(IF(COUNTIFS(할일표[날짜],J$7,할일표[업무],"<>")<4,"",INDEX(할일표[진행률],SMALL(IF((할일표[날짜]=J$7)*(할일표[업무]<>""),ROW(할일표[날짜])-피벗!$T$11),4))),"")} | N11: {=IFERROR(IF(COUNTIFS(할일표[날짜],N$7,할일표[업무],"<>")<4,"",INDEX(구분표[아이콘],MATCH(INDEX(할일표[구분],SMALL(IF((할일표[날짜]=N$7)*(할일표[업무]<>""),ROW(할일표[구분])-ROW(INDEX(할일표[구분],1))+1),4)),구분표[구분],0))),"")} | O11: {=IFERROR(IF(COUNTIFS(할일표[날짜],N$7,할일표[업무],"<>")<4,"",INDEX(할일표[표시],SMALL(IF((할일표[날짜]=N$7)*(할일표[업무]<>""),ROW(할일표[표시])-ROW(INDEX(할일표[표시],1))+1),4))),"")} | P11: {=IFERROR(IF(COUNTIFS(할일표[날짜],N$7,할일표[업무],"<>")<4,"",INDEX(할일표[업무],SMALL(IF((할일표[날짜]=N$7)*(할일표[업무]<>""),ROW(할일표[날짜])-피벗!$T$11),4))),"")} | Q11: {=IFERROR(IF(COUNTIFS(할일표[날짜],N$7,할일표[업무],"<>")<4,"",INDEX(할일표[진행률],SMALL(IF((할일표[날짜]=N$7)*(할일표[업무]<>""),ROW(할일표[날짜])-피벗!$T$11),4))),"")} | R11: {=IFERROR(IF(COUNTIFS(할일표[날짜],R$7,할일표[업무],"<>")<4,"",INDEX(구분표[아이콘],MATCH(INDEX(할일표[구분],SMALL(IF((할일표[날짜]=R$7)*(할일표[업무]<>""),ROW(할일표[구분])-ROW(INDEX(할일표[구분],1))+1),4)),구분표[구분],0))),"")} | S11: {=IFERROR(IF(COUNTIFS(할일표[날짜],R$7,할일표[업무],"<>")<4,"",INDEX(할일표[표시],SMALL(IF((할일표[날짜]=R$7)*(할일표[업무]<>""),ROW(할일표[표시])-ROW(INDEX(할일표[표시],1))+1),4))),"")} | T11: {=IFERROR(IF(COUNTIFS(할일표[날짜],R$7,할일표[업무],"<>")<4,"",INDEX(할일표[업무],SMALL(IF((할일표[날짜]=R$7)*(할일표[업무]<>""),ROW(할일표[날짜])-피벗!$T$11),4))),"")} | U11: {=IFERROR(IF(COUNTIFS(할일표[날짜],R$7,할일표[업무],"<>")<4,"",INDEX(할일표[진행률],SMALL(IF((할일표[날짜]=R$7)*(할일표[업무]<>""),ROW(할일표[날짜])-피벗!$T$11),4))),"")} | V11: {=IFERROR(IF(COUNTIFS(할일표[날짜],V$7,할일표[업무],"<>")<4,"",INDEX(구분표[아이콘],MATCH(INDEX(할일표[구분],SMALL(IF((할일표[날짜]=V$7)*(할일표[업무]<>""),ROW(할일표[구분])-ROW(INDEX(할일표[구분],1))+1),4)),구분표[구분],0))),"")} | W11: {=IFERROR(IF(COUNTIFS(할일표[날짜],V$7,할일표[업무],"<>")<4,"",INDEX(할일표[표시],SMALL(IF((할일표[날짜]=V$7)*(할일표[업무]<>""),ROW(할일표[표시])-ROW(INDEX(할일표[표시],1))+1),4))),"")} | X11: {=IFERROR(IF(COUNTIFS(할일표[날짜],V$7,할일표[업무],"<>")<4,"",INDEX(할일표[업무],SMALL(IF((할일표[날짜]=V$7)*(할일표[업무]<>""),ROW(할일표[날짜])-피벗!$T$11),4))),"")} | Y11: {=IFERROR(IF(COUNTIFS(할일표[날짜],V$7,할일표[업무],"<>")<4,"",INDEX(할일표[진행률],SMALL(IF((할일표[날짜]=V$7)*(할일표[업무]<>""),ROW(할일표[날짜])-피벗!$T$11),4))),"")} | Z11: {=IFERROR(IF(COUNTIFS(할일표[날짜],Z$7,할일표[업무],"<>")<4,"",INDEX(구분표[아이콘],MATCH(INDEX(할일표[구분],SMALL(IF((할일표[날짜]=Z$7)*(할일표[업무]<>""),ROW(할일표[구분])-ROW(INDEX(할일표[구분],1))+1),4)),구분표[구분],0))),"")} | AA11: {=IFERROR(IF(COUNTIFS(할일표[날짜],Z$7,할일표[업무],"<>")<4,"",INDEX(할일표[표시],SMALL(IF((할일표[날짜]=Z$7)*(할일표[업무]<>""),ROW(할일표[표시])-ROW(INDEX(할일표[표시],1))+1),4))),"")} | AB11: {=IFERROR(IF(COUNTIFS(할일표[날짜],Z$7,할일표[업무],"<>")<4,"",INDEX(할일표[업무],SMALL(IF((할일표[날짜]=Z$7)*(할일표[업무]<>""),ROW(할일표[날짜])-피벗!$T$11),4))),"")} | AC11: {=IFERROR(IF(COUNTIFS(할일표[날짜],Z$7,할일표[업무],"<>")<4,"",INDEX(할일표[진행률],SMALL(IF((할일표[날짜]=Z$7)*(할일표[업무]<>""),ROW(할일표[날짜])-피벗!$T$11),4))),"")} | AJ11: =RAND() -> 0.77701427 | AK11: =RAND() -> 0.9785631 | AL11: =RAND() -> 0.55515455 | AM11: =RAND() -> 0.52518972 | AN11: =RAND() -> 0.58953972 | AO11: =RAND() -> 0.076561397 | AP11: =RAND() -> 0.36195433
B12: {=IFERROR(IF(COUNTIFS(할일표[날짜],B$7,할일표[업무],"<>")<5,"",INDEX(구분표[아이콘],MATCH(INDEX(할일표[구분],SMALL(IF((할일표[날짜]=B$7)*(할일표[업무]<>""),ROW(할일표[구분])-ROW(INDEX(할일표[구분],1))+1),5)),구분표[구분],0))),"")} | C12: {=IFERROR(IF(COUNTIFS(할일표[날짜],B$7,할일표[업무],"<>")<5,"",INDEX(할일표[표시],SMALL(IF((할일표[날짜]=B$7)*(할일표[업무]<>""),ROW(할일표[표시])-ROW(INDEX(할일표[표시],1))+1),5))),"")} | D12: {=IFERROR(IF(COUNTIFS(할일표[날짜],B$7,할일표[업무],"<>")<5,"",INDEX(할일표[업무],SMALL(IF((할일표[날짜]=B$7)*(할일표[업무]<>""),ROW(할일표[날짜])-피벗!$T$11),5))),"")} | E12: {=IFERROR(IF(COUNTIFS(할일표[날짜],B$7,할일표[업무],"<>")<5,"",INDEX(할일표[진행률],SMALL(IF((할일표[날짜]=B$7)*(할일표[업무]<>""),ROW(할일표[날짜])-피벗!$T$11),5))),"")} | F12: {=IFERROR(IF(COUNTIFS(할일표[날짜],F$7,할일표[업무],"<>")<5,"",INDEX(구분표[아이콘],MATCH(INDEX(할일표[구분],SMALL(IF((할일표[날짜]=F$7)*(할일표[업무]<>""),ROW(할일표[구분])-ROW(INDEX(할일표[구분],1))+1),5)),구분표[구분],0))),"")} | G12: {=IFERROR(IF(COUNTIFS(할일표[날짜],F$7,할일표[업무],"<>")<5,"",INDEX(할일표[표시],SMALL(IF((할일표[날짜]=F$7)*(할일표[업무]<>""),ROW(할일표[표시])-ROW(INDEX(할일표[표시],1))+1),5))),"")} | H12: {=IFERROR(IF(COUNTIFS(할일표[날짜],F$7,할일표[업무],"<>")<5,"",INDEX(할일표[업무],SMALL(IF((할일표[날짜]=F$7)*(할일표[업무]<>""),ROW(할일표[날짜])-피벗!$T$11),5))),"")} | I12: {=IFERROR(IF(COUNTIFS(할일표[날짜],F$7,할일표[업무],"<>")<5,"",INDEX(할일표[진행률],SMALL(IF((할일표[날짜]=F$7)*(할일표[업무]<>""),ROW(할일표[날짜])-피벗!$T$11),5))),"")} | J12: {=IFERROR(IF(COUNTIFS(할일표[날짜],J$7,할일표[업무],"<>")<5,"",INDEX(구분표[아이콘],MATCH(INDEX(할일표[구분],SMALL(IF((할일표[날짜]=J$7)*(할일표[업무]<>""),ROW(할일표[구분])-ROW(INDEX(할일표[구분],1))+1),5)),구분표[구분],0))),"")} | K12: {=IFERROR(IF(COUNTIFS(할일표[날짜],J$7,할일표[업무],"<>")<5,"",INDEX(할일표[표시],SMALL(IF((할일표[날짜]=J$7)*(할일표[업무]<>""),ROW(할일표[표시])-ROW(INDEX(할일표[표시],1))+1),5))),"")} | L12: {=IFERROR(IF(COUNTIFS(할일표[날짜],J$7,할일표[업무],"<>")<5,"",INDEX(할일표[업무],SMALL(IF((할일표[날짜]=J$7)*(할일표[업무]<>""),ROW(할일표[날짜])-피벗!$T$11),5))),"")} | M12: {=IFERROR(IF(COUNTIFS(할일표[날짜],J$7,할일표[업무],"<>")<5,"",INDEX(할일표[진행률],SMALL(IF((할일표[날짜]=J$7)*(할일표[업무]<>""),ROW(할일표[날짜])-피벗!$T$11),5))),"")} | N12: {=IFERROR(IF(COUNTIFS(할일표[날짜],N$7,할일표[업무],"<>")<5,"",INDEX(구분표[아이콘],MATCH(INDEX(할일표[구분],SMALL(IF((할일표[날짜]=N$7)*(할일표[업무]<>""),ROW(할일표[구분])-ROW(INDEX(할일표[구분],1))+1),5)),구분표[구분],0))),"")} | O12: {=IFERROR(IF(COUNTIFS(할일표[날짜],N$7,할일표[업무],"<>")<5,"",INDEX(할일표[표시],SMALL(IF((할일표[날짜]=N$7)*(할일표[업무]<>""),ROW(할일표[표시])-ROW(INDEX(할일표[표시],1))+1),5))),"")} | P12: {=IFERROR(IF(COUNTIFS(할일표[날짜],N$7,할일표[업무],"<>")<5,"",INDEX(할일표[업무],SMALL(IF((할일표[날짜]=N$7)*(할일표[업무]<>""),ROW(할일표[날짜])-피벗!$T$11),5))),"")} | Q12: {=IFERROR(IF(COUNTIFS(할일표[날짜],N$7,할일표[업무],"<>")<5,"",INDEX(할일표[진행률],SMALL(IF((할일표[날짜]=N$7)*(할일표[업무]<>""),ROW(할일표[날짜])-피벗!$T$11),5))),"")} | R12: {=IFERROR(IF(COUNTIFS(할일표[날짜],R$7,할일표[업무],"<>")<5,"",INDEX(구분표[아이콘],MATCH(INDEX(할일표[구분],SMALL(IF((할일표[날짜]=R$7)*(할일표[업무]<>""),ROW(할일표[구분])-ROW(INDEX(할일표[구분],1))+1),5)),구분표[구분],0))),"")} | S12: {=IFERROR(IF(COUNTIFS(할일표[날짜],R$7,할일표[업무],"<>")<5,"",INDEX(할일표[표시],SMALL(IF((할일표[날짜]=R$7)*(할일표[업무]<>""),ROW(할일표[표시])-ROW(INDEX(할일표[표시],1))+1),5))),"")} | T12: {=IFERROR(IF(COUNTIFS(할일표[날짜],R$7,할일표[업무],"<>")<5,"",INDEX(할일표[업무],SMALL(IF((할일표[날짜]=R$7)*(할일표[업무]<>""),ROW(할일표[날짜])-피벗!$T$11),5))),"")} | U12: {=IFERROR(IF(COUNTIFS(할일표[날짜],R$7,할일표[업무],"<>")<5,"",INDEX(할일표[진행률],SMALL(IF((할일표[날짜]=R$7)*(할일표[업무]<>""),ROW(할일표[날짜])-피벗!$T$11),5))),"")} | V12: {=IFERROR(IF(COUNTIFS(할일표[날짜],V$7,할일표[업무],"<>")<5,"",INDEX(구분표[아이콘],MATCH(INDEX(할일표[구분],SMALL(IF((할일표[날짜]=V$7)*(할일표[업무]<>""),ROW(할일표[구분])-ROW(INDEX(할일표[구분],1))+1),5)),구분표[구분],0))),"")} | W12: {=IFERROR(IF(COUNTIFS(할일표[날짜],V$7,할일표[업무],"<>")<5,"",INDEX(할일표[표시],SMALL(IF((할일표[날짜]=V$7)*(할일표[업무]<>""),ROW(할일표[표시])-ROW(INDEX(할일표[표시],1))+1),5))),"")} | X12: {=IFERROR(IF(COUNTIFS(할일표[날짜],V$7,할일표[업무],"<>")<5,"",INDEX(할일표[업무],SMALL(IF((할일표[날짜]=V$7)*(할일표[업무]<>""),ROW(할일표[날짜])-피벗!$T$11),5))),"")} | Y12: {=IFERROR(IF(COUNTIFS(할일표[날짜],V$7,할일표[업무],"<>")<5,"",INDEX(할일표[진행률],SMALL(IF((할일표[날짜]=V$7)*(할일표[업무]<>""),ROW(할일표[날짜])-피벗!$T$11),5))),"")} | Z12: {=IFERROR(IF(COUNTIFS(할일표[날짜],Z$7,할일표[업무],"<>")<5,"",INDEX(구분표[아이콘],MATCH(INDEX(할일표[구분],SMALL(IF((할일표[날짜]=Z$7)*(할일표[업무]<>""),ROW(할일표[구분])-ROW(INDEX(할일표[구분],1))+1),5)),구분표[구분],0))),"")} | AA12: {=IFERROR(IF(COUNTIFS(할일표[날짜],Z$7,할일표[업무],"<>")<5,"",INDEX(할일표[표시],SMALL(IF((할일표[날짜]=Z$7)*(할일표[업무]<>""),ROW(할일표[표시])-ROW(INDEX(할일표[표시],1))+1),5))),"")} | AB12: {=IFERROR(IF(COUNTIFS(할일표[날짜],Z$7,할일표[업무],"<>")<5,"",INDEX(할일표[업무],SMALL(IF((할일표[날짜]=Z$7)*(할일표[업무]<>""),ROW(할일표[날짜])-피벗!$T$11),5))),"")} | AC12: {=IFERROR(IF(COUNTIFS(할일표[날짜],Z$7,할일표[업무],"<>")<5,"",INDEX(할일표[진행률],SMALL(IF((할일표[날짜]=Z$7)*(할일표[업무]<>""),ROW(할일표[날짜])-피벗!$T$11),5))),"")} | AJ12: =RAND() -> 0.53601844 | AK12: =RAND() -> 0.064125507 | AL12: =RAND() -> 0.61386593 | AM12: =RAND() -> 0.56466023 | AN12: =RAND() -> 0.33911561 | AO12: =RAND() -> 0.12627392 | AP12: =RAND() -> 0.42399016
B13: {=IFERROR(IF(COUNTIFS(할일표[날짜],B$7,할일표[업무],"<>")<6,"",INDEX(구분표[아이콘],MATCH(INDEX(할일표[구분],SMALL(IF((할일표[날짜]=B$7)*(할일표[업무]<>""),ROW(할일표[구분])-ROW(INDEX(할일표[구분],1))+1),6)),구분표[구분],0))),"")} | C13: {=IFERROR(IF(COUNTIFS(할일표[날짜],B$7,할일표[업무],"<>")<6,"",INDEX(할일표[표시],SMALL(IF((할일표[날짜]=B$7)*(할일표[업무]<>""),ROW(할일표[표시])-ROW(INDEX(할일표[표시],1))+1),6))),"")} | D13: {=IFERROR(IF(COUNTIFS(할일표[날짜],B$7,할일표[업무],"<>")<6,"",INDEX(할일표[업무],SMALL(IF((할일표[날짜]=B$7)*(할일표[업무]<>""),ROW(할일표[날짜])-피벗!$T$11),6))),"")} | E13: {=IFERROR(IF(COUNTIFS(할일표[날짜],B$7,할일표[업무],"<>")<6,"",INDEX(할일표[진행률],SMALL(IF((할일표[날짜]=B$7)*(할일표[업무]<>""),ROW(할일표[날짜])-피벗!$T$11),6))),"")} | F13: {=IFERROR(IF(COUNTIFS(할일표[날짜],F$7,할일표[업무],"<>")<6,"",INDEX(구분표[아이콘],MATCH(INDEX(할일표[구분],SMALL(IF((할일표[날짜]=F$7)*(할일표[업무]<>""),ROW(할일표[구분])-ROW(INDEX(할일표[구분],1))+1),6)),구분표[구분],0))),"")} | G13: {=IFERROR(IF(COUNTIFS(할일표[날짜],F$7,할일표[업무],"<>")<6,"",INDEX(할일표[표시],SMALL(IF((할일표[날짜]=F$7)*(할일표[업무]<>""),ROW(할일표[표시])-ROW(INDEX(할일표[표시],1))+1),6))),"")} | H13: {=IFERROR(IF(COUNTIFS(할일표[날짜],F$7,할일표[업무],"<>")<6,"",INDEX(할일표[업무],SMALL(IF((할일표[날짜]=F$7)*(할일표[업무]<>""),ROW(할일표[날짜])-피벗!$T$11),6))),"")} | I13: {=IFERROR(IF(COUNTIFS(할일표[날짜],F$7,할일표[업무],"<>")<6,"",INDEX(할일표[진행률],SMALL(IF((할일표[날짜]=F$7)*(할일표[업무]<>""),ROW(할일표[날짜])-피벗!$T$11),6))),"")} | J13: {=IFERROR(IF(COUNTIFS(할일표[날짜],J$7,할일표[업무],"<>")<6,"",INDEX(구분표[아이콘],MATCH(INDEX(할일표[구분],SMALL(IF((할일표[날짜]=J$7)*(할일표[업무]<>""),ROW(할일표[구분])-ROW(INDEX(할일표[구분],1))+1),6)),구분표[구분],0))),"")} | K13: {=IFERROR(IF(COUNTIFS(할일표[날짜],J$7,할일표[업무],"<>")<6,"",INDEX(할일표[표시],SMALL(IF((할일표[날짜]=J$7)*(할일표[업무]<>""),ROW(할일표[표시])-ROW(INDEX(할일표[표시],1))+1),6))),"")} | L13: {=IFERROR(IF(COUNTIFS(할일표[날짜],J$7,할일표[업무],"<>")<6,"",INDEX(할일표[업무],SMALL(IF((할일표[날짜]=J$7)*(할일표[업무]<>""),ROW(할일표[날짜])-피벗!$T$11),6))),"")} | M13: {=IFERROR(IF(COUNTIFS(할일표[날짜],J$7,할일표[업무],"<>")<6,"",INDEX(할일표[진행률],SMALL(IF((할일표[날짜]=J$7)*(할일표[업무]<>""),ROW(할일표[날짜])-피벗!$T$11),6))),"")} | N13: {=IFERROR(IF(COUNTIFS(할일표[날짜],N$7,할일표[업무],"<>")<6,"",INDEX(구분표[아이콘],MATCH(INDEX(할일표[구분],SMALL(IF((할일표[날짜]=N$7)*(할일표[업무]<>""),ROW(할일표[구분])-ROW(INDEX(할일표[구분],1))+1),6)),구분표[구분],0))),"")} | O13: {=IFERROR(IF(COUNTIFS(할일표[날짜],N$7,할일표[업무],"<>")<6,"",INDEX(할일표[표시],SMALL(IF((할일표[날짜]=N$7)*(할일표[업무]<>""),ROW(할일표[표시])-ROW(INDEX(할일표[표시],1))+1),6))),"")} | P13: {=IFERROR(IF(COUNTIFS(할일표[날짜],N$7,할일표[업무],"<>")<6,"",INDEX(할일표[업무],SMALL(IF((할일표[날짜]=N$7)*(할일표[업무]<>""),ROW(할일표[날짜])-피벗!$T$11),6))),"")} | Q13: {=IFERROR(IF(COUNTIFS(할일표[날짜],N$7,할일표[업무],"<>")<6,"",INDEX(할일표[진행률],SMALL(IF((할일표[날짜]=N$7)*(할일표[업무]<>""),ROW(할일표[날짜])-피벗!$T$11),6))),"")} | R13: {=IFERROR(IF(COUNTIFS(할일표[날짜],R$7,할일표[업무],"<>")<6,"",INDEX(구분표[아이콘],MATCH(INDEX(할일표[구분],SMALL(IF((할일표[날짜]=R$7)*(할일표[업무]<>""),ROW(할일표[구분])-ROW(INDEX(할일표[구분],1))+1),6)),구분표[구분],0))),"")} | S13: {=IFERROR(IF(COUNTIFS(할일표[날짜],R$7,할일표[업무],"<>")<6,"",INDEX(할일표[표시],SMALL(IF((할일표[날짜]=R$7)*(할일표[업무]<>""),ROW(할일표[표시])-ROW(INDEX(할일표[표시],1))+1),6))),"")} | T13: {=IFERROR(IF(COUNTIFS(할일표[날짜],R$7,할일표[업무],"<>")<6,"",INDEX(할일표[업무],SMALL(IF((할일표[날짜]=R$7)*(할일표[업무]<>""),ROW(할일표[날짜])-피벗!$T$11),6))),"")} | U13: {=IFERROR(IF(COUNTIFS(할일표[날짜],R$7,할일표[업무],"<>")<6,"",INDEX(할일표[진행률],SMALL(IF((할일표[날짜]=R$7)*(할일표[업무]<>""),ROW(할일표[날짜])-피벗!$T$11),6))),"")} | V13: {=IFERROR(IF(COUNTIFS(할일표[날짜],V$7,할일표[업무],"<>")<6,"",INDEX(구분표[아이콘],MATCH(INDEX(할일표[구분],SMALL(IF((할일표[날짜]=V$7)*(할일표[업무]<>""),ROW(할일표[구분])-ROW(INDEX(할일표[구분],1))+1),6)),구분표[구분],0))),"")} | W13: {=IFERROR(IF(COUNTIFS(할일표[날짜],V$7,할일표[업무],"<>")<6,"",INDEX(할일표[표시],SMALL(IF((할일표[날짜]=V$7)*(할일표[업무]<>""),ROW(할일표[표시])-ROW(INDEX(할일표[표시],1))+1),6))),"")} | X13: {=IFERROR(IF(COUNTIFS(할일표[날짜],V$7,할일표[업무],"<>")<6,"",INDEX(할일표[업무],SMALL(IF((할일표[날짜]=V$7)*(할일표[업무]<>""),ROW(할일표[날짜])-피벗!$T$11),6))),"")} | Y13: {=IFERROR(IF(COUNTIFS(할일표[날짜],V$7,할일표[업무],"<>")<6,"",INDEX(할일표[진행률],SMALL(IF((할일표[날짜]=V$7)*(할일표[업무]<>""),ROW(할일표[날짜])-피벗!$T$11),6))),"")} | Z13: {=IFERROR(IF(COUNTIFS(할일표[날짜],Z$7,할일표[업무],"<>")<6,"",INDEX(구분표[아이콘],MATCH(INDEX(할일표[구분],SMALL(IF((할일표[날짜]=Z$7)*(할일표[업무]<>""),ROW(할일표[구분])-ROW(INDEX(할일표[구분],1))+1),6)),구분표[구분],0))),"")} | AA13: {=IFERROR(IF(COUNTIFS(할일표[날짜],Z$7,할일표[업무],"<>")<6,"",INDEX(할일표[표시],SMALL(IF((할일표[날짜]=Z$7)*(할일표[업무]<>""),ROW(할일표[표시])-ROW(INDEX(할일표[표시],1))+1),6))),"")} | AB13: {=IFERROR(IF(COUNTIFS(할일표[날짜],Z$7,할일표[업무],"<>")<6,"",INDEX(할일표[업무],SMALL(IF((할일표[날짜]=Z$7)*(할일표[업무]<>""),ROW(할일표[날짜])-피벗!$T$11),6))),"")} | AC13: {=IFERROR(IF(COUNTIFS(할일표[날짜],Z$7,할일표[업무],"<>")<6,"",INDEX(할일표[진행률],SMALL(IF((할일표[날짜]=Z$7)*(할일표[업무]<>""),ROW(할일표[날짜])-피벗!$T$11),6))),"")} | AI13: =RAND() -> 0.65704775 | AJ13: =RAND() -> 0.74751713 | AK13: =RAND() -> 0.54552499 | AL13: =RAND() -> 0.92137769 | AM13: =RAND() -> 0.0042573141 | AN13: =RAND() -> 0.50821214 | AO13: =RAND() -> 0.26466438 | AP13: =RAND() -> 0.6768214 | AQ13: =RAND() -> 0.64755702
B14: {=IFERROR(IF(COUNTIFS(할일표[날짜],B$7,할일표[업무],"<>")<7,"",INDEX(구분표[아이콘],MATCH(INDEX(할일표[구분],SMALL(IF((할일표[날짜]=B$7)*(할일표[업무]<>""),ROW(할일표[구분])-ROW(INDEX(할일표[구분],1))+1),7)),구분표[구분],0))),"")} | C14: {=IFERROR(IF(COUNTIFS(할일표[날짜],B$7,할일표[업무],"<>")<7,"",INDEX(할일표[표시],SMALL(IF((할일표[날짜]=B$7)*(할일표[업무]<>""),ROW(할일표[표시])-ROW(INDEX(할일표[표시],1))+1),7))),"")} | D14: {=IFERROR(IF(COUNTIFS(할일표[날짜],B$7,할일표[업무],"<>")<7,"",INDEX(할일표[업무],SMALL(IF((할일표[날짜]=B$7)*(할일표[업무]<>""),ROW(할일표[날짜])-피벗!$T$11),7))),"")} | E14: {=IFERROR(IF(COUNTIFS(할일표[날짜],B$7,할일표[업무],"<>")<7,"",INDEX(할일표[진행률],SMALL(IF((할일표[날짜]=B$7)*(할일표[업무]<>""),ROW(할일표[날짜])-피벗!$T$11),7))),"")} | F14: {=IFERROR(IF(COUNTIFS(할일표[날짜],F$7,할일표[업무],"<>")<7,"",INDEX(구분표[아이콘],MATCH(INDEX(할일표[구분],SMALL(IF((할일표[날짜]=F$7)*(할일표[업무]<>""),ROW(할일표[구분])-ROW(INDEX(할일표[구분],1))+1),7)),구분표[구분],0))),"")} | G14: {=IFERROR(IF(COUNTIFS(할일표[날짜],F$7,할일표[업무],"<>")<7,"",INDEX(할일표[표시],SMALL(IF((할일표[날짜]=F$7)*(할일표[업무]<>""),ROW(할일표[표시])-ROW(INDEX(할일표[표시],1))+1),7))),"")} | H14: {=IFERROR(IF(COUNTIFS(할일표[날짜],F$7,할일표[업무],"<>")<7,"",INDEX(할일표[업무],SMALL(IF((할일표[날짜]=F$7)*(할일표[업무]<>""),ROW(할일표[날짜])-피벗!$T$11),7))),"")} | I14: {=IFERROR(IF(COUNTIFS(할일표[날짜],F$7,할일표[업무],"<>")<7,"",INDEX(할일표[진행률],SMALL(IF((할일표[날짜]=F$7)*(할일표[업무]<>""),ROW(할일표[날짜])-피벗!$T$11),7))),"")} | J14: {=IFERROR(IF(COUNTIFS(할일표[날짜],J$7,할일표[업무],"<>")<7,"",INDEX(구분표[아이콘],MATCH(INDEX(할일표[구분],SMALL(IF((할일표[날짜]=J$7)*(할일표[업무]<>""),ROW(할일표[구분])-ROW(INDEX(할일표[구분],1))+1),7)),구분표[구분],0))),"")} | K14: {=IFERROR(IF(COUNTIFS(할일표[날짜],J$7,할일표[업무],"<>")<7,"",INDEX(할일표[표시],SMALL(IF((할일표[날짜]=J$7)*(할일표[업무]<>""),ROW(할일표[표시])-ROW(INDEX(할일표[표시],1))+1),7))),"")} | L14: {=IFERROR(IF(COUNTIFS(할일표[날짜],J$7,할일표[업무],"<>")<7,"",INDEX(할일표[업무],SMALL(IF((할일표[날짜]=J$7)*(할일표[업무]<>""),ROW(할일표[날짜])-피벗!$T$11),7))),"")} | M14: {=IFERROR(IF(COUNTIFS(할일표[날짜],J$7,할일표[업무],"<>")<7,"",INDEX(할일표[진행률],SMALL(IF((할일표[날짜]=J$7)*(할일표[업무]<>""),ROW(할일표[날짜])-피벗!$T$11),7))),"")} | N14: {=IFERROR(IF(COUNTIFS(할일표[날짜],N$7,할일표[업무],"<>")<7,"",INDEX(구분표[아이콘],MATCH(INDEX(할일표[구분],SMALL(IF((할일표[날짜]=N$7)*(할일표[업무]<>""),ROW(할일표[구분])-ROW(INDEX(할일표[구분],1))+1),7)),구분표[구분],0))),"")} | O14: {=IFERROR(IF(COUNTIFS(할일표[날짜],N$7,할일표[업무],"<>")<7,"",INDEX(할일표[표시],SMALL(IF((할일표[날짜]=N$7)*(할일표[업무]<>""),ROW(할일표[표시])-ROW(INDEX(할일표[표시],1))+1),7))),"")} | P14: {=IFERROR(IF(COUNTIFS(할일표[날짜],N$7,할일표[업무],"<>")<7,"",INDEX(할일표[업무],SMALL(IF((할일표[날짜]=N$7)*(할일표[업무]<>""),ROW(할일표[날짜])-피벗!$T$11),7))),"")} | Q14: {=IFERROR(IF(COUNTIFS(할일표[날짜],N$7,할일표[업무],"<>")<7,"",INDEX(할일표[진행률],SMALL(IF((할일표[날짜]=N$7)*(할일표[업무]<>""),ROW(할일표[날짜])-피벗!$T$11),7))),"")} | R14: {=IFERROR(IF(COUNTIFS(할일표[날짜],R$7,할일표[업무],"<>")<7,"",INDEX(구분표[아이콘],MATCH(INDEX(할일표[구분],SMALL(IF((할일표[날짜]=R$7)*(할일표[업무]<>""),ROW(할일표[구분])-ROW(INDEX(할일표[구분],1))+1),7)),구분표[구분],0))),"")} | S14: {=IFERROR(IF(COUNTIFS(할일표[날짜],R$7,할일표[업무],"<>")<7,"",INDEX(할일표[표시],SMALL(IF((할일표[날짜]=R$7)*(할일표[업무]<>""),ROW(할일표[표시])-ROW(INDEX(할일표[표시],1))+1),7))),"")} | T14: {=IFERROR(IF(COUNTIFS(할일표[날짜],R$7,할일표[업무],"<>")<7,"",INDEX(할일표[업무],SMALL(IF((할일표[날짜]=R$7)*(할일표[업무]<>""),ROW(할일표[날짜])-피벗!$T$11),7))),"")} | U14: {=IFERROR(IF(COUNTIFS(할일표[날짜],R$7,할일표[업무],"<>")<7,"",INDEX(할일표[진행률],SMALL(IF((할일표[날짜]=R$7)*(할일표[업무]<>""),ROW(할일표[날짜])-피벗!$T$11),7))),"")} | V14: {=IFERROR(IF(COUNTIFS(할일표[날짜],V$7,할일표[업무],"<>")<7,"",INDEX(구분표[아이콘],MATCH(INDEX(할일표[구분],SMALL(IF((할일표[날짜]=V$7)*(할일표[업무]<>""),ROW(할일표[구분])-ROW(INDEX(할일표[구분],1))+1),7)),구분표[구분],0))),"")} | W14: {=IFERROR(IF(COUNTIFS(할일표[날짜],V$7,할일표[업무],"<>")<7,"",INDEX(할일표[표시],SMALL(IF((할일표[날짜]=V$7)*(할일표[업무]<>""),ROW(할일표[표시])-ROW(INDEX(할일표[표시],1))+1),7))),"")} | X14: {=IFERROR(IF(COUNTIFS(할일표[날짜],V$7,할일표[업무],"<>")<7,"",INDEX(할일표[업무],SMALL(IF((할일표[날짜]=V$7)*(할일표[업무]<>""),ROW(할일표[날짜])-피벗!$T$11),7))),"")} | Y14: {=IFERROR(IF(COUNTIFS(할일표[날짜],V$7,할일표[업무],"<>")<7,"",INDEX(할일표[진행률],SMALL(IF((할일표[날짜]=V$7)*(할일표[업무]<>""),ROW(할일표[날짜])-피벗!$T$11),7))),"")} | Z14: {=IFERROR(IF(COUNTIFS(할일표[날짜],Z$7,할일표[업무],"<>")<7,"",INDEX(구분표[아이콘],MATCH(INDEX(할일표[구분],SMALL(IF((할일표[날짜]=Z$7)*(할일표[업무]<>""),ROW(할일표[구분])-ROW(INDEX(할일표[구분],1))+1),7)),구분표[구분],0))),"")} | AA14: {=IFERROR(IF(COUNTIFS(할일표[날짜],Z$7,할일표[업무],"<>")<7,"",INDEX(할일표[표시],SMALL(IF((할일표[날짜]=Z$7)*(할일표[업무]<>""),ROW(할일표[표시])-ROW(INDEX(할일표[표시],1))+1),7))),"")} | AB14: {=IFERROR(IF(COUNTIFS(할일표[날짜],Z$7,할일표[업무],"<>")<7,"",INDEX(할일표[업무],SMALL(IF((할일표[날짜]=Z$7)*(할일표[업무]<>""),ROW(할일표[날짜])-피벗!$T$11),7))),"")} | AC14: {=IFERROR(IF(COUNTIFS(할일표[날짜],Z$7,할일표[업무],"<>")<7,"",INDEX(할일표[진행률],SMALL(IF((할일표[날짜]=Z$7)*(할일표[업무]<>""),ROW(할일표[날짜])-피벗!$T$11),7))),"")}
B15: {=IFERROR(IF(COUNTIFS(할일표[날짜],B$7,할일표[업무],"<>")<8,"",INDEX(구분표[아이콘],MATCH(INDEX(할일표[구분],SMALL(IF((할일표[날짜]=B$7)*(할일표[업무]<>""),ROW(할일표[구분])-ROW(INDEX(할일표[구분],1))+1),8)),구분표[구분],0))),"")} | C15: {=IFERROR(IF(COUNTIFS(할일표[날짜],B$7,할일표[업무],"<>")<8,"",INDEX(할일표[표시],SMALL(IF((할일표[날짜]=B$7)*(할일표[업무]<>""),ROW(할일표[표시])-ROW(INDEX(할일표[표시],1))+1),8))),"")} | D15: {=IFERROR(IF(COUNTIFS(할일표[날짜],B$7,할일표[업무],"<>")<8,"",INDEX(할일표[업무],SMALL(IF((할일표[날짜]=B$7)*(할일표[업무]<>""),ROW(할일표[날짜])-피벗!$T$11),8))),"")} | E15: {=IFERROR(IF(COUNTIFS(할일표[날짜],B$7,할일표[업무],"<>")<8,"",INDEX(할일표[진행률],SMALL(IF((할일표[날짜]=B$7)*(할일표[업무]<>""),ROW(할일표[날짜])-피벗!$T$11),8))),"")} | F15: {=IFERROR(IF(COUNTIFS(할일표[날짜],F$7,할일표[업무],"<>")<8,"",INDEX(구분표[아이콘],MATCH(INDEX(할일표[구분],SMALL(IF((할일표[날짜]=F$7)*(할일표[업무]<>""),ROW(할일표[구분])-ROW(INDEX(할일표[구분],1))+1),8)),구분표[구분],0))),"")} | G15: {=IFERROR(IF(COUNTIFS(할일표[날짜],F$7,할일표[업무],"<>")<8,"",INDEX(할일표[표시],SMALL(IF((할일표[날짜]=F$7)*(할일표[업무]<>""),ROW(할일표[표시])-ROW(INDEX(할일표[표시],1))+1),8))),"")} | H15: {=IFERROR(IF(COUNTIFS(할일표[날짜],F$7,할일표[업무],"<>")<8,"",INDEX(할일표[업무],SMALL(IF((할일표[날짜]=F$7)*(할일표[업무]<>""),ROW(할일표[날짜])-피벗!$T$11),8))),"")} | I15: {=IFERROR(IF(COUNTIFS(할일표[날짜],F$7,할일표[업무],"<>")<8,"",INDEX(할일표[진행률],SMALL(IF((할일표[날짜]=F$7)*(할일표[업무]<>""),ROW(할일표[날짜])-피벗!$T$11),8))),"")} | J15: {=IFERROR(IF(COUNTIFS(할일표[날짜],J$7,할일표[업무],"<>")<8,"",INDEX(구분표[아이콘],MATCH(INDEX(할일표[구분],SMALL(IF((할일표[날짜]=J$7)*(할일표[업무]<>""),ROW(할일표[구분])-ROW(INDEX(할일표[구분],1))+1),8)),구분표[구분],0))),"")} | K15: {=IFERROR(IF(COUNTIFS(할일표[날짜],J$7,할일표[업무],"<>")<8,"",INDEX(할일표[표시],SMALL(IF((할일표[날짜]=J$7)*(할일표[업무]<>""),ROW(할일표[표시])-ROW(INDEX(할일표[표시],1))+1),8))),"")} | L15: {=IFERROR(IF(COUNTIFS(할일표[날짜],J$7,할일표[업무],"<>")<8,"",INDEX(할일표[업무],SMALL(IF((할일표[날짜]=J$7)*(할일표[업무]<>""),ROW(할일표[날짜])-피벗!$T$11),8))),"")} | M15: {=IFERROR(IF(COUNTIFS(할일표[날짜],J$7,할일표[업무],"<>")<8,"",INDEX(할일표[진행률],SMALL(IF((할일표[날짜]=J$7)*(할일표[업무]<>""),ROW(할일표[날짜])-피벗!$T$11),8))),"")} | N15: {=IFERROR(IF(COUNTIFS(할일표[날짜],N$7,할일표[업무],"<>")<8,"",INDEX(구분표[아이콘],MATCH(INDEX(할일표[구분],SMALL(IF((할일표[날짜]=N$7)*(할일표[업무]<>""),ROW(할일표[구분])-ROW(INDEX(할일표[구분],1))+1),8)),구분표[구분],0))),"")} | O15: {=IFERROR(IF(COUNTIFS(할일표[날짜],N$7,할일표[업무],"<>")<8,"",INDEX(할일표[표시],SMALL(IF((할일표[날짜]=N$7)*(할일표[업무]<>""),ROW(할일표[표시])-ROW(INDEX(할일표[표시],1))+1),8))),"")} | P15: {=IFERROR(IF(COUNTIFS(할일표[날짜],N$7,할일표[업무],"<>")<8,"",INDEX(할일표[업무],SMALL(IF((할일표[날짜]=N$7)*(할일표[업무]<>""),ROW(할일표[날짜])-피벗!$T$11),8))),"")} | Q15: {=IFERROR(IF(COUNTIFS(할일표[날짜],N$7,할일표[업무],"<>")<8,"",INDEX(할일표[진행률],SMALL(IF((할일표[날짜]=N$7)*(할일표[업무]<>""),ROW(할일표[날짜])-피벗!$T$11),8))),"")} | R15: {=IFERROR(IF(COUNTIFS(할일표[날짜],R$7,할일표[업무],"<>")<8,"",INDEX(구분표[아이콘],MATCH(INDEX(할일표[구분],SMALL(IF((할일표[날짜]=R$7)*(할일표[업무]<>""),ROW(할일표[구분])-ROW(INDEX(할일표[구분],1))+1),8)),구분표[구분],0))),"")} | S15: {=IFERROR(IF(COUNTIFS(할일표[날짜],R$7,할일표[업무],"<>")<8,"",INDEX(할일표[표시],SMALL(IF((할일표[날짜]=R$7)*(할일표[업무]<>""),ROW(할일표[표시])-ROW(INDEX(할일표[표시],1))+1),8))),"")} | T15: {=IFERROR(IF(COUNTIFS(할일표[날짜],R$7,할일표[업무],"<>")<8,"",INDEX(할일표[업무],SMALL(IF((할일표[날짜]=R$7)*(할일표[업무]<>""),ROW(할일표[날짜])-피벗!$T$11),8))),"")} | U15: {=IFERROR(IF(COUNTIFS(할일표[날짜],R$7,할일표[업무],"<>")<8,"",INDEX(할일표[진행률],SMALL(IF((할일표[날짜]=R$7)*(할일표[업무]<>""),ROW(할일표[날짜])-피벗!$T$11),8))),"")} | V15: {=IFERROR(IF(COUNTIFS(할일표[날짜],V$7,할일표[업무],"<>")<8,"",INDEX(구분표[아이콘],MATCH(INDEX(할일표[구분],SMALL(IF((할일표[날짜]=V$7)*(할일표[업무]<>""),ROW(할일표[구분])-ROW(INDEX(할일표[구분],1))+1),8)),구분표[구분],0))),"")} | W15: {=IFERROR(IF(COUNTIFS(할일표[날짜],V$7,할일표[업무],"<>")<8,"",INDEX(할일표[표시],SMALL(IF((할일표[날짜]=V$7)*(할일표[업무]<>""),ROW(할일표[표시])-ROW(INDEX(할일표[표시],1))+1),8))),"")} | X15: {=IFERROR(IF(COUNTIFS(할일표[날짜],V$7,할일표[업무],"<>")<8,"",INDEX(할일표[업무],SMALL(IF((할일표[날짜]=V$7)*(할일표[업무]<>""),ROW(할일표[날짜])-피벗!$T$11),8))),"")} | Y15: {=IFERROR(IF(COUNTIFS(할일표[날짜],V$7,할일표[업무],"<>")<8,"",INDEX(할일표[진행률],SMALL(IF((할일표[날짜]=V$7)*(할일표[업무]<>""),ROW(할일표[날짜])-피벗!$T$11),8))),"")} | Z15: {=IFERROR(IF(COUNTIFS(할일표[날짜],Z$7,할일표[업무],"<>")<8,"",INDEX(구분표[아이콘],MATCH(INDEX(할일표[구분],SMALL(IF((할일표[날짜]=Z$7)*(할일표[업무]<>""),ROW(할일표[구분])-ROW(INDEX(할일표[구분],1))+1),8)),구분표[구분],0))),"")} | AA15: {=IFERROR(IF(COUNTIFS(할일표[날짜],Z$7,할일표[업무],"<>")<8,"",INDEX(할일표[표시],SMALL(IF((할일표[날짜]=Z$7)*(할일표[업무]<>""),ROW(할일표[표시])-ROW(INDEX(할일표[표시],1))+1),8))),"")} | AB15: {=IFERROR(IF(COUNTIFS(할일표[날짜],Z$7,할일표[업무],"<>")<8,"",INDEX(할일표[업무],SMALL(IF((할일표[날짜]=Z$7)*(할일표[업무]<>""),ROW(할일표[날짜])-피벗!$T$11),8))),"")} | AC15: {=IFERROR(IF(COUNTIFS(할일표[날짜],Z$7,할일표[업무],"<>")<8,"",INDEX(할일표[진행률],SMALL(IF((할일표[날짜]=Z$7)*(할일표[업무]<>""),ROW(할일표[날짜])-피벗!$T$11),8))),"")}
B17: =Z7+1 -> 46271 | F17: =B17+1 -> 46272 | J17: =F17+1 -> 46273 | N17: =J17+1 -> 46274 | R17: =N17+1 -> 46275 | V17: =R17+1 -> 46276 | Z17: =V17+1 -> 46277
B18: {=IFERROR(IF(COUNTIFS(할일표[날짜],B$17,할일표[업무],"<>")<1,"",INDEX(구분표[아이콘],MATCH(INDEX(할일표[구분],SMALL(IF((할일표[날짜]=B$17)*(할일표[업무]<>""),ROW(할일표[구분])-ROW(INDEX(할일표[구분],1))+1),1)),구분표[구분],0))),"")} | C18: {=IFERROR(IF(COUNTIFS(할일표[날짜],B$17,할일표[업무],"<>")<1,"",INDEX(할일표[표시],SMALL(IF((할일표[날짜]=B$17)*(할일표[업무]<>""),ROW(할일표[표시])-ROW(INDEX(할일표[표시],1))+1),1))),"")} | D18: {=IFERROR(IF(COUNTIFS(할일표[날짜],B$17,할일표[업무],"<>")<1,"",INDEX(할일표[업무],SMALL(IF((할일표[날짜]=B$17)*(할일표[업무]<>""),ROW(할일표[날짜])-피벗!$T$11),1))),"")} | E18: {=IFERROR(IF(COUNTIFS(할일표[날짜],B$17,할일표[업무],"<>")<1,"",INDEX(할일표[진행률],SMALL(IF((할일표[날짜]=B$17)*(할일표[업무]<>""),ROW(할일표[날짜])-피벗!$T$11),1))),"")} | F18: {=IFERROR(IF(COUNTIFS(할일표[날짜],F$17,할일표[업무],"<>")<1,"",INDEX(구분표[아이콘],MATCH(INDEX(할일표[구분],SMALL(IF((할일표[날짜]=F$17)*(할일표[업무]<>""),ROW(할일표[구분])-ROW(INDEX(할일표[구분],1))+1),1)),구분표[구분],0))),"")} | G18: {=IFERROR(IF(COUNTIFS(할일표[날짜],F$17,할일표[업무],"<>")<1,"",INDEX(할일표[표시],SMALL(IF((할일표[날짜]=F$17)*(할일표[업무]<>""),ROW(할일표[표시])-ROW(INDEX(할일표[표시],1))+1),1))),"")} | H18: {=IFERROR(IF(COUNTIFS(할일표[날짜],F$17,할일표[업무],"<>")<1,"",INDEX(할일표[업무],SMALL(IF((할일표[날짜]=F$17)*(할일표[업무]<>""),ROW(할일표[날짜])-피벗!$T$11),1))),"")} | I18: {=IFERROR(IF(COUNTIFS(할일표[날짜],F$17,할일표[업무],"<>")<1,"",INDEX(할일표[진행률],SMALL(IF((할일표[날짜]=F$17)*(할일표[업무]<>""),ROW(할일표[날짜])-피벗!$T$11),1))),"")} | J18: {=IFERROR(IF(COUNTIFS(할일표[날짜],J$17,할일표[업무],"<>")<1,"",INDEX(구분표[아이콘],MATCH(INDEX(할일표[구분],SMALL(IF((할일표[날짜]=J$17)*(할일표[업무]<>""),ROW(할일표[구분])-ROW(INDEX(할일표[구분],1))+1),1)),구분표[구분],0))),"")} | K18: {=IFERROR(IF(COUNTIFS(할일표[날짜],J$17,할일표[업무],"<>")<1,"",INDEX(할일표[표시],SMALL(IF((할일표[날짜]=J$17)*(할일표[업무]<>""),ROW(할일표[표시])-ROW(INDEX(할일표[표시],1))+1),1))),"")} | L18: {=IFERROR(IF(COUNTIFS(할일표[날짜],J$17,할일표[업무],"<>")<1,"",INDEX(할일표[업무],SMALL(IF((할일표[날짜]=J$17)*(할일표[업무]<>""),ROW(할일표[날짜])-피벗!$T$11),1))),"")} | M18: {=IFERROR(IF(COUNTIFS(할일표[날짜],J$17,할일표[업무],"<>")<1,"",INDEX(할일표[진행률],SMALL(IF((할일표[날짜]=J$17)*(할일표[업무]<>""),ROW(할일표[날짜])-피벗!$T$11),1))),"")} | N18: {=IFERROR(IF(COUNTIFS(할일표[날짜],N$17,할일표[업무],"<>")<1,"",INDEX(구분표[아이콘],MATCH(INDEX(할일표[구분],SMALL(IF((할일표[날짜]=N$17)*(할일표[업무]<>""),ROW(할일표[구분])-ROW(INDEX(할일표[구분],1))+1),1)),구분표[구분],0))),"")} | O18: {=IFERROR(IF(COUNTIFS(할일표[날짜],N$17,할일표[업무],"<>")<1,"",INDEX(할일표[표시],SMALL(IF((할일표[날짜]=N$17)*(할일표[업무]<>""),ROW(할일표[표시])-ROW(INDEX(할일표[표시],1))+1),1))),"")} | P18: {=IFERROR(IF(COUNTIFS(할일표[날짜],N$17,할일표[업무],"<>")<1,"",INDEX(할일표[업무],SMALL(IF((할일표[날짜]=N$17)*(할일표[업무]<>""),ROW(할일표[날짜])-피벗!$T$11),1))),"")} | Q18: {=IFERROR(IF(COUNTIFS(할일표[날짜],N$17,할일표[업무],"<>")<1,"",INDEX(할일표[진행률],SMALL(IF((할일표[날짜]=N$17)*(할일표[업무]<>""),ROW(할일표[날짜])-피벗!$T$11),1))),"")} | R18: {=IFERROR(IF(COUNTIFS(할일표[날짜],R$17,할일표[업무],"<>")<1,"",INDEX(구분표[아이콘],MATCH(INDEX(할일표[구분],SMALL(IF((할일표[날짜]=R$17)*(할일표[업무]<>""),ROW(할일표[구분])-ROW(INDEX(할일표[구분],1))+1),1)),구분표[구분],0))),"")} | S18: {=IFERROR(IF(COUNTIFS(할일표[날짜],R$17,할일표[업무],"<>")<1,"",INDEX(할일표[표시],SMALL(IF((할일표[날짜]=R$17)*(할일표[업무]<>""),ROW(할일표[표시])-ROW(INDEX(할일표[표시],1))+1),1))),"")} | T18: {=IFERROR(IF(COUNTIFS(할일표[날짜],R$17,할일표[업무],"<>")<1,"",INDEX(할일표[업무],SMALL(IF((할일표[날짜]=R$17)*(할일표[업무]<>""),ROW(할일표[날짜])-피벗!$T$11),1))),"")} | U18: {=IFERROR(IF(COUNTIFS(할일표[날짜],R$17,할일표[업무],"<>")<1,"",INDEX(할일표[진행률],SMALL(IF((할일표[날짜]=R$17)*(할일표[업무]<>""),ROW(할일표[날짜])-피벗!$T$11),1))),"")} | V18: {=IFERROR(IF(COUNTIFS(할일표[날짜],V$17,할일표[업무],"<>")<1,"",INDEX(구분표[아이콘],MATCH(INDEX(할일표[구분],SMALL(IF((할일표[날짜]=V$17)*(할일표[업무]<>""),ROW(할일표[구분])-ROW(INDEX(할일표[구분],1))+1),1)),구분표[구분],0))),"")} | W18: {=IFERROR(IF(COUNTIFS(할일표[날짜],V$17,할일표[업무],"<>")<1,"",INDEX(할일표[표시],SMALL(IF((할일표[날짜]=V$17)*(할일표[업무]<>""),ROW(할일표[표시])-ROW(INDEX(할일표[표시],1))+1),1))),"")} | X18: {=IFERROR(IF(COUNTIFS(할일표[날짜],V$17,할일표[업무],"<>")<1,"",INDEX(할일표[업무],SMALL(IF((할일표[날짜]=V$17)*(할일표[업무]<>""),ROW(할일표[날짜])-피벗!$T$11),1))),"")} | Y18: {=IFERROR(IF(COUNTIFS(할일표[날짜],V$17,할일표[업무],"<>")<1,"",INDEX(할일표[진행률],SMALL(IF((할일표[날짜]=V$17)*(할일표[업무]<>""),ROW(할일표[날짜])-피벗!$T$11),1))),"")} | Z18: {=IFERROR(IF(COUNTIFS(할일표[날짜],Z$17,할일표[업무],"<>")<1,"",INDEX(구분표[아이콘],MATCH(INDEX(할일표[구분],SMALL(IF((할일표[날짜]=Z$17)*(할일표[업무]<>""),ROW(할일표[구분])-ROW(INDEX(할일표[구분],1))+1),1)),구분표[구분],0))),"")} | AA18: {=IFERROR(IF(COUNTIFS(할일표[날짜],Z$17,할일표[업무],"<>")<1,"",INDEX(할일표[표시],SMALL(IF((할일표[날짜]=Z$17)*(할일표[업무]<>""),ROW(할일표[표시])-ROW(INDEX(할일표[표시],1))+1),1))),"")} | AB18: {=IFERROR(IF(COUNTIFS(할일표[날짜],Z$17,할일표[업무],"<>")<1,"",INDEX(할일표[업무],SMALL(IF((할일표[날짜]=Z$17)*(할일표[업무]<>""),ROW(할일표[날짜])-피벗!$T$11),1))),"")} | AC18: {=IFERROR(IF(COUNTIFS(할일표[날짜],Z$17,할일표[업무],"<>")<1,"",INDEX(할일표[진행률],SMALL(IF((할일표[날짜]=Z$17)*(할일표[업무]<>""),ROW(할일표[날짜])-피벗!$T$11),1))),"")}
B19: {=IFERROR(IF(COUNTIFS(할일표[날짜],B$17,할일표[업무],"<>")<2,"",INDEX(구분표[아이콘],MATCH(INDEX(할일표[구분],SMALL(IF((할일표[날짜]=B$17)*(할일표[업무]<>""),ROW(할일표[구분])-ROW(INDEX(할일표[구분],1))+1),2)),구분표[구분],0))),"")} | C19: {=IFERROR(IF(COUNTIFS(할일표[날짜],B$17,할일표[업무],"<>")<2,"",INDEX(할일표[표시],SMALL(IF((할일표[날짜]=B$17)*(할일표[업무]<>""),ROW(할일표[표시])-ROW(INDEX(할일표[표시],1))+1),2))),"")} | D19: {=IFERROR(IF(COUNTIFS(할일표[날짜],B$17,할일표[업무],"<>")<2,"",INDEX(할일표[업무],SMALL(IF((할일표[날짜]=B$17)*(할일표[업무]<>""),ROW(할일표[날짜])-피벗!$T$11),2))),"")} | E19: {=IFERROR(IF(COUNTIFS(할일표[날짜],B$17,할일표[업무],"<>")<2,"",INDEX(할일표[진행률],SMALL(IF((할일표[날짜]=B$17)*(할일표[업무]<>""),ROW(할일표[날짜])-피벗!$T$11),2))),"")} | F19: {=IFERROR(IF(COUNTIFS(할일표[날짜],F$17,할일표[업무],"<>")<2,"",INDEX(구분표[아이콘],MATCH(INDEX(할일표[구분],SMALL(IF((할일표[날짜]=F$17)*(할일표[업무]<>""),ROW(할일표[구분])-ROW(INDEX(할일표[구분],1))+1),2)),구분표[구분],0))),"")} | G19: {=IFERROR(IF(COUNTIFS(할일표[날짜],F$17,할일표[업무],"<>")<2,"",INDEX(할일표[표시],SMALL(IF((할일표[날짜]=F$17)*(할일표[업무]<>""),ROW(할일표[표시])-ROW(INDEX(할일표[표시],1))+1),2))),"")} | H19: {=IFERROR(IF(COUNTIFS(할일표[날짜],F$17,할일표[업무],"<>")<2,"",INDEX(할일표[업무],SMALL(IF((할일표[날짜]=F$17)*(할일표[업무]<>""),ROW(할일표[날짜])-피벗!$T$11),2))),"")} | I19: {=IFERROR(IF(COUNTIFS(할일표[날짜],F$17,할일표[업무],"<>")<2,"",INDEX(할일표[진행률],SMALL(IF((할일표[날짜]=F$17)*(할일표[업무]<>""),ROW(할일표[날짜])-피벗!$T$11),2))),"")} | J19: {=IFERROR(IF(COUNTIFS(할일표[날짜],J$17,할일표[업무],"<>")<2,"",INDEX(구분표[아이콘],MATCH(INDEX(할일표[구분],SMALL(IF((할일표[날짜]=J$17)*(할일표[업무]<>""),ROW(할일표[구분])-ROW(INDEX(할일표[구분],1))+1),2)),구분표[구분],0))),"")} | K19: {=IFERROR(IF(COUNTIFS(할일표[날짜],J$17,할일표[업무],"<>")<2,"",INDEX(할일표[표시],SMALL(IF((할일표[날짜]=J$17)*(할일표[업무]<>""),ROW(할일표[표시])-ROW(INDEX(할일표[표시],1))+1),2))),"")} | L19: {=IFERROR(IF(COUNTIFS(할일표[날짜],J$17,할일표[업무],"<>")<2,"",INDEX(할일표[업무],SMALL(IF((할일표[날짜]=J$17)*(할일표[업무]<>""),ROW(할일표[날짜])-피벗!$T$11),2))),"")} | M19: {=IFERROR(IF(COUNTIFS(할일표[날짜],J$17,할일표[업무],"<>")<2,"",INDEX(할일표[진행률],SMALL(IF((할일표[날짜]=J$17)*(할일표[업무]<>""),ROW(할일표[날짜])-피벗!$T$11),2))),"")} | N19: {=IFERROR(IF(COUNTIFS(할일표[날짜],N$17,할일표[업무],"<>")<2,"",INDEX(구분표[아이콘],MATCH(INDEX(할일표[구분],SMALL(IF((할일표[날짜]=N$17)*(할일표[업무]<>""),ROW(할일표[구분])-ROW(INDEX(할일표[구분],1))+1),2)),구분표[구분],0))),"")} | O19: {=IFERROR(IF(COUNTIFS(할일표[날짜],N$17,할일표[업무],"<>")<2,"",INDEX(할일표[표시],SMALL(IF((할일표[날짜]=N$17)*(할일표[업무]<>""),ROW(할일표[표시])-ROW(INDEX(할일표[표시],1))+1),2))),"")} | P19: {=IFERROR(IF(COUNTIFS(할일표[날짜],N$17,할일표[업무],"<>")<2,"",INDEX(할일표[업무],SMALL(IF((할일표[날짜]=N$17)*(할일표[업무]<>""),ROW(할일표[날짜])-피벗!$T$11),2))),"")} | Q19: {=IFERROR(IF(COUNTIFS(할일표[날짜],N$17,할일표[업무],"<>")<2,"",INDEX(할일표[진행률],SMALL(IF((할일표[날짜]=N$17)*(할일표[업무]<>""),ROW(할일표[날짜])-피벗!$T$11),2))),"")} | R19: {=IFERROR(IF(COUNTIFS(할일표[날짜],R$17,할일표[업무],"<>")<2,"",INDEX(구분표[아이콘],MATCH(INDEX(할일표[구분],SMALL(IF((할일표[날짜]=R$17)*(할일표[업무]<>""),ROW(할일표[구분])-ROW(INDEX(할일표[구분],1))+1),2)),구분표[구분],0))),"")} | S19: {=IFERROR(IF(COUNTIFS(할일표[날짜],R$17,할일표[업무],"<>")<2,"",INDEX(할일표[표시],SMALL(IF((할일표[날짜]=R$17)*(할일표[업무]<>""),ROW(할일표[표시])-ROW(INDEX(할일표[표시],1))+1),2))),"")} | T19: {=IFERROR(IF(COUNTIFS(할일표[날짜],R$17,할일표[업무],"<>")<2,"",INDEX(할일표[업무],SMALL(IF((할일표[날짜]=R$17)*(할일표[업무]<>""),ROW(할일표[날짜])-피벗!$T$11),2))),"")} | U19: {=IFERROR(IF(COUNTIFS(할일표[날짜],R$17,할일표[업무],"<>")<2,"",INDEX(할일표[진행률],SMALL(IF((할일표[날짜]=R$17)*(할일표[업무]<>""),ROW(할일표[날짜])-피벗!$T$11),2))),"")} | V19: {=IFERROR(IF(COUNTIFS(할일표[날짜],V$17,할일표[업무],"<>")<2,"",INDEX(구분표[아이콘],MATCH(INDEX(할일표[구분],SMALL(IF((할일표[날짜]=V$17)*(할일표[업무]<>""),ROW(할일표[구분])-ROW(INDEX(할일표[구분],1))+1),2)),구분표[구분],0))),"")} | W19: {=IFERROR(IF(COUNTIFS(할일표[날짜],V$17,할일표[업무],"<>")<2,"",INDEX(할일표[표시],SMALL(IF((할일표[날짜]=V$17)*(할일표[업무]<>""),ROW(할일표[표시])-ROW(INDEX(할일표[표시],1))+1),2))),"")} | X19: {=IFERROR(IF(COUNTIFS(할일표[날짜],V$17,할일표[업무],"<>")<2,"",INDEX(할일표[업무],SMALL(IF((할일표[날짜]=V$17)*(할일표[업무]<>""),ROW(할일표[날짜])-피벗!$T$11),2))),"")} | Y19: {=IFERROR(IF(COUNTIFS(할일표[날짜],V$17,할일표[업무],"<>")<2,"",INDEX(할일표[진행률],SMALL(IF((할일표[날짜]=V$17)*(할일표[업무]<>""),ROW(할일표[날짜])-피벗!$T$11),2))),"")} | Z19: {=IFERROR(IF(COUNTIFS(할일표[날짜],Z$17,할일표[업무],"<>")<2,"",INDEX(구분표[아이콘],MATCH(INDEX(할일표[구분],SMALL(IF((할일표[날짜]=Z$17)*(할일표[업무]<>""),ROW(할일표[구분])-ROW(INDEX(할일표[구분],1))+1),2)),구분표[구분],0))),"")} | AA19: {=IFERROR(IF(COUNTIFS(할일표[날짜],Z$17,할일표[업무],"<>")<2,"",INDEX(할일표[표시],SMALL(IF((할일표[날짜]=Z$17)*(할일표[업무]<>""),ROW(할일표[표시])-ROW(INDEX(할일표[표시],1))+1),2))),"")} | AB19: {=IFERROR(IF(COUNTIFS(할일표[날짜],Z$17,할일표[업무],"<>")<2,"",INDEX(할일표[업무],SMALL(IF((할일표[날짜]=Z$17)*(할일표[업무]<>""),ROW(할일표[날짜])-피벗!$T$11),2))),"")} | AC19: {=IFERROR(IF(COUNTIFS(할일표[날짜],Z$17,할일표[업무],"<>")<2,"",INDEX(할일표[진행률],SMALL(IF((할일표[날짜]=Z$17)*(할일표[업무]<>""),ROW(할일표[날짜])-피벗!$T$11),2))),"")}
B20: {=IFERROR(IF(COUNTIFS(할일표[날짜],B$17,할일표[업무],"<>")<3,"",INDEX(구분표[아이콘],MATCH(INDEX(할일표[구분],SMALL(IF((할일표[날짜]=B$17)*(할일표[업무]<>""),ROW(할일표[구분])-ROW(INDEX(할일표[구분],1))+1),3)),구분표[구분],0))),"")} | C20: {=IFERROR(IF(COUNTIFS(할일표[날짜],B$17,할일표[업무],"<>")<3,"",INDEX(할일표[표시],SMALL(IF((할일표[날짜]=B$17)*(할일표[업무]<>""),ROW(할일표[표시])-ROW(INDEX(할일표[표시],1))+1),3))),"")} | D20: {=IFERROR(IF(COUNTIFS(할일표[날짜],B$17,할일표[업무],"<>")<3,"",INDEX(할일표[업무],SMALL(IF((할일표[날짜]=B$17)*(할일표[업무]<>""),ROW(할일표[날짜])-피벗!$T$11),3))),"")} | E20: {=IFERROR(IF(COUNTIFS(할일표[날짜],B$17,할일표[업무],"<>")<3,"",INDEX(할일표[진행률],SMALL(IF((할일표[날짜]=B$17)*(할일표[업무]<>""),ROW(할일표[날짜])-피벗!$T$11),3))),"")} | F20: {=IFERROR(IF(COUNTIFS(할일표[날짜],F$17,할일표[업무],"<>")<3,"",INDEX(구분표[아이콘],MATCH(INDEX(할일표[구분],SMALL(IF((할일표[날짜]=F$17)*(할일표[업무]<>""),ROW(할일표[구분])-ROW(INDEX(할일표[구분],1))+1),3)),구분표[구분],0))),"")} | G20: {=IFERROR(IF(COUNTIFS(할일표[날짜],F$17,할일표[업무],"<>")<3,"",INDEX(할일표[표시],SMALL(IF((할일표[날짜]=F$17)*(할일표[업무]<>""),ROW(할일표[표시])-ROW(INDEX(할일표[표시],1))+1),3))),"")} | H20: {=IFERROR(IF(COUNTIFS(할일표[날짜],F$17,할일표[업무],"<>")<3,"",INDEX(할일표[업무],SMALL(IF((할일표[날짜]=F$17)*(할일표[업무]<>""),ROW(할일표[날짜])-피벗!$T$11),3))),"")} | I20: {=IFERROR(IF(COUNTIFS(할일표[날짜],F$17,할일표[업무],"<>")<3,"",INDEX(할일표[진행률],SMALL(IF((할일표[날짜]=F$17)*(할일표[업무]<>""),ROW(할일표[날짜])-피벗!$T$11),3))),"")} | J20: {=IFERROR(IF(COUNTIFS(할일표[날짜],J$17,할일표[업무],"<>")<3,"",INDEX(구분표[아이콘],MATCH(INDEX(할일표[구분],SMALL(IF((할일표[날짜]=J$17)*(할일표[업무]<>""),ROW(할일표[구분])-ROW(INDEX(할일표[구분],1))+1),3)),구분표[구분],0))),"")} | K20: {=IFERROR(IF(COUNTIFS(할일표[날짜],J$17,할일표[업무],"<>")<3,"",INDEX(할일표[표시],SMALL(IF((할일표[날짜]=J$17)*(할일표[업무]<>""),ROW(할일표[표시])-ROW(INDEX(할일표[표시],1))+1),3))),"")} | L20: {=IFERROR(IF(COUNTIFS(할일표[날짜],J$17,할일표[업무],"<>")<3,"",INDEX(할일표[업무],SMALL(IF((할일표[날짜]=J$17)*(할일표[업무]<>""),ROW(할일표[날짜])-피벗!$T$11),3))),"")} | M20: {=IFERROR(IF(COUNTIFS(할일표[날짜],J$17,할일표[업무],"<>")<3,"",INDEX(할일표[진행률],SMALL(IF((할일표[날짜]=J$17)*(할일표[업무]<>""),ROW(할일표[날짜])-피벗!$T$11),3))),"")} | N20: {=IFERROR(IF(COUNTIFS(할일표[날짜],N$17,할일표[업무],"<>")<3,"",INDEX(구분표[아이콘],MATCH(INDEX(할일표[구분],SMALL(IF((할일표[날짜]=N$17)*(할일표[업무]<>""),ROW(할일표[구분])-ROW(INDEX(할일표[구분],1))+1),3)),구분표[구분],0))),"")} | O20: {=IFERROR(IF(COUNTIFS(할일표[날짜],N$17,할일표[업무],"<>")<3,"",INDEX(할일표[표시],SMALL(IF((할일표[날짜]=N$17)*(할일표[업무]<>""),ROW(할일표[표시])-ROW(INDEX(할일표[표시],1))+1),3))),"")} | P20: {=IFERROR(IF(COUNTIFS(할일표[날짜],N$17,할일표[업무],"<>")<3,"",INDEX(할일표[업무],SMALL(IF((할일표[날짜]=N$17)*(할일표[업무]<>""),ROW(할일표[날짜])-피벗!$T$11),3))),"")} | Q20: {=IFERROR(IF(COUNTIFS(할일표[날짜],N$17,할일표[업무],"<>")<3,"",INDEX(할일표[진행률],SMALL(IF((할일표[날짜]=N$17)*(할일표[업무]<>""),ROW(할일표[날짜])-피벗!$T$11),3))),"")} | R20: {=IFERROR(IF(COUNTIFS(할일표[날짜],R$17,할일표[업무],"<>")<3,"",INDEX(구분표[아이콘],MATCH(INDEX(할일표[구분],SMALL(IF((할일표[날짜]=R$17)*(할일표[업무]<>""),ROW(할일표[구분])-ROW(INDEX(할일표[구분],1))+1),3)),구분표[구분],0))),"")} | S20: {=IFERROR(IF(COUNTIFS(할일표[날짜],R$17,할일표[업무],"<>")<3,"",INDEX(할일표[표시],SMALL(IF((할일표[날짜]=R$17)*(할일표[업무]<>""),ROW(할일표[표시])-ROW(INDEX(할일표[표시],1))+1),3))),"")} | T20: {=IFERROR(IF(COUNTIFS(할일표[날짜],R$17,할일표[업무],"<>")<3,"",INDEX(할일표[업무],SMALL(IF((할일표[날짜]=R$17)*(할일표[업무]<>""),ROW(할일표[날짜])-피벗!$T$11),3))),"")} | U20: {=IFERROR(IF(COUNTIFS(할일표[날짜],R$17,할일표[업무],"<>")<3,"",INDEX(할일표[진행률],SMALL(IF((할일표[날짜]=R$17)*(할일표[업무]<>""),ROW(할일표[날짜])-피벗!$T$11),3))),"")} | V20: {=IFERROR(IF(COUNTIFS(할일표[날짜],V$17,할일표[업무],"<>")<3,"",INDEX(구분표[아이콘],MATCH(INDEX(할일표[구분],SMALL(IF((할일표[날짜]=V$17)*(할일표[업무]<>""),ROW(할일표[구분])-ROW(INDEX(할일표[구분],1))+1),3)),구분표[구분],0))),"")} | W20: {=IFERROR(IF(COUNTIFS(할일표[날짜],V$17,할일표[업무],"<>")<3,"",INDEX(할일표[표시],SMALL(IF((할일표[날짜]=V$17)*(할일표[업무]<>""),ROW(할일표[표시])-ROW(INDEX(할일표[표시],1))+1),3))),"")} | X20: {=IFERROR(IF(COUNTIFS(할일표[날짜],V$17,할일표[업무],"<>")<3,"",INDEX(할일표[업무],SMALL(IF((할일표[날짜]=V$17)*(할일표[업무]<>""),ROW(할일표[날짜])-피벗!$T$11),3))),"")} | Y20: {=IFERROR(IF(COUNTIFS(할일표[날짜],V$17,할일표[업무],"<>")<3,"",INDEX(할일표[진행률],SMALL(IF((할일표[날짜]=V$17)*(할일표[업무]<>""),ROW(할일표[날짜])-피벗!$T$11),3))),"")} | Z20: {=IFERROR(IF(COUNTIFS(할일표[날짜],Z$17,할일표[업무],"<>")<3,"",INDEX(구분표[아이콘],MATCH(INDEX(할일표[구분],SMALL(IF((할일표[날짜]=Z$17)*(할일표[업무]<>""),ROW(할일표[구분])-ROW(INDEX(할일표[구분],1))+1),3)),구분표[구분],0))),"")} | AA20: {=IFERROR(IF(COUNTIFS(할일표[날짜],Z$17,할일표[업무],"<>")<3,"",INDEX(할일표[표시],SMALL(IF((할일표[날짜]=Z$17)*(할일표[업무]<>""),ROW(할일표[표시])-ROW(INDEX(할일표[표시],1))+1),3))),"")} | AB20: {=IFERROR(IF(COUNTIFS(할일표[날짜],Z$17,할일표[업무],"<>")<3,"",INDEX(할일표[업무],SMALL(IF((할일표[날짜]=Z$17)*(할일표[업무]<>""),ROW(할일표[날짜])-피벗!$T$11),3))),"")} | AC20: {=IFERROR(IF(COUNTIFS(할일표[날짜],Z$17,할일표[업무],"<>")<3,"",INDEX(할일표[진행률],SMALL(IF((할일표[날짜]=Z$17)*(할일표[업무]<>""),ROW(할일표[날짜])-피벗!$T$11),3))),"")}
B21: {=IFERROR(IF(COUNTIFS(할일표[날짜],B$17,할일표[업무],"<>")<4,"",INDEX(구분표[아이콘],MATCH(INDEX(할일표[구분],SMALL(IF((할일표[날짜]=B$17)*(할일표[업무]<>""),ROW(할일표[구분])-ROW(INDEX(할일표[구분],1))+1),4)),구분표[구분],0))),"")} | C21: {=IFERROR(IF(COUNTIFS(할일표[날짜],B$17,할일표[업무],"<>")<4,"",INDEX(할일표[표시],SMALL(IF((할일표[날짜]=B$17)*(할일표[업무]<>""),ROW(할일표[표시])-ROW(INDEX(할일표[표시],1))+1),4))),"")} | D21: {=IFERROR(IF(COUNTIFS(할일표[날짜],B$17,할일표[업무],"<>")<4,"",INDEX(할일표[업무],SMALL(IF((할일표[날짜]=B$17)*(할일표[업무]<>""),ROW(할일표[날짜])-피벗!$T$11),4))),"")} | E21: {=IFERROR(IF(COUNTIFS(할일표[날짜],B$17,할일표[업무],"<>")<4,"",INDEX(할일표[진행률],SMALL(IF((할일표[날짜]=B$17)*(할일표[업무]<>""),ROW(할일표[날짜])-피벗!$T$11),4))),"")} | F21: {=IFERROR(IF(COUNTIFS(할일표[날짜],F$17,할일표[업무],"<>")<4,"",INDEX(구분표[아이콘],MATCH(INDEX(할일표[구분],SMALL(IF((할일표[날짜]=F$17)*(할일표[업무]<>""),ROW(할일표[구분])-ROW(INDEX(할일표[구분],1))+1),4)),구분표[구분],0))),"")} | G21: {=IFERROR(IF(COUNTIFS(할일표[날짜],F$17,할일표[업무],"<>")<4,"",INDEX(할일표[표시],SMALL(IF((할일표[날짜]=F$17)*(할일표[업무]<>""),ROW(할일표[표시])-ROW(INDEX(할일표[표시],1))+1),4))),"")} | H21: {=IFERROR(IF(COUNTIFS(할일표[날짜],F$17,할일표[업무],"<>")<4,"",INDEX(할일표[업무],SMALL(IF((할일표[날짜]=F$17)*(할일표[업무]<>""),ROW(할일표[날짜])-피벗!$T$11),4))),"")} | I21: {=IFERROR(IF(COUNTIFS(할일표[날짜],F$17,할일표[업무],"<>")<4,"",INDEX(할일표[진행률],SMALL(IF((할일표[날짜]=F$17)*(할일표[업무]<>""),ROW(할일표[날짜])-피벗!$T$11),4))),"")} | J21: {=IFERROR(IF(COUNTIFS(할일표[날짜],J$17,할일표[업무],"<>")<4,"",INDEX(구분표[아이콘],MATCH(INDEX(할일표[구분],SMALL(IF((할일표[날짜]=J$17)*(할일표[업무]<>""),ROW(할일표[구분])-ROW(INDEX(할일표[구분],1))+1),4)),구분표[구분],0))),"")} | K21: {=IFERROR(IF(COUNTIFS(할일표[날짜],J$17,할일표[업무],"<>")<4,"",INDEX(할일표[표시],SMALL(IF((할일표[날짜]=J$17)*(할일표[업무]<>""),ROW(할일표[표시])-ROW(INDEX(할일표[표시],1))+1),4))),"")} | L21: {=IFERROR(IF(COUNTIFS(할일표[날짜],J$17,할일표[업무],"<>")<4,"",INDEX(할일표[업무],SMALL(IF((할일표[날짜]=J$17)*(할일표[업무]<>""),ROW(할일표[날짜])-피벗!$T$11),4))),"")} | M21: {=IFERROR(IF(COUNTIFS(할일표[날짜],J$17,할일표[업무],"<>")<4,"",INDEX(할일표[진행률],SMALL(IF((할일표[날짜]=J$17)*(할일표[업무]<>""),ROW(할일표[날짜])-피벗!$T$11),4))),"")} | N21: {=IFERROR(IF(COUNTIFS(할일표[날짜],N$17,할일표[업무],"<>")<4,"",INDEX(구분표[아이콘],MATCH(INDEX(할일표[구분],SMALL(IF((할일표[날짜]=N$17)*(할일표[업무]<>""),ROW(할일표[구분])-ROW(INDEX(할일표[구분],1))+1),4)),구분표[구분],0))),"")} | O21: {=IFERROR(IF(COUNTIFS(할일표[날짜],N$17,할일표[업무],"<>")<4,"",INDEX(할일표[표시],SMALL(IF((할일표[날짜]=N$17)*(할일표[업무]<>""),ROW(할일표[표시])-ROW(INDEX(할일표[표시],1))+1),4))),"")} | P21: {=IFERROR(IF(COUNTIFS(할일표[날짜],N$17,할일표[업무],"<>")<4,"",INDEX(할일표[업무],SMALL(IF((할일표[날짜]=N$17)*(할일표[업무]<>""),ROW(할일표[날짜])-피벗!$T$11),4))),"")} | Q21: {=IFERROR(IF(COUNTIFS(할일표[날짜],N$17,할일표[업무],"<>")<4,"",INDEX(할일표[진행률],SMALL(IF((할일표[날짜]=N$17)*(할일표[업무]<>""),ROW(할일표[날짜])-피벗!$T$11),4))),"")} | R21: {=IFERROR(IF(COUNTIFS(할일표[날짜],R$17,할일표[업무],"<>")<4,"",INDEX(구분표[아이콘],MATCH(INDEX(할일표[구분],SMALL(IF((할일표[날짜]=R$17)*(할일표[업무]<>""),ROW(할일표[구분])-ROW(INDEX(할일표[구분],1))+1),4)),구분표[구분],0))),"")} | S21: {=IFERROR(IF(COUNTIFS(할일표[날짜],R$17,할일표[업무],"<>")<4,"",INDEX(할일표[표시],SMALL(IF((할일표[날짜]=R$17)*(할일표[업무]<>""),ROW(할일표[표시])-ROW(INDEX(할일표[표시],1))+1),4))),"")} | T21: {=IFERROR(IF(COUNTIFS(할일표[날짜],R$17,할일표[업무],"<>")<4,"",INDEX(할일표[업무],SMALL(IF((할일표[날짜]=R$17)*(할일표[업무]<>""),ROW(할일표[날짜])-피벗!$T$11),4))),"")} | U21: {=IFERROR(IF(COUNTIFS(할일표[날짜],R$17,할일표[업무],"<>")<4,"",INDEX(할일표[진행률],SMALL(IF((할일표[날짜]=R$17)*(할일표[업무]<>""),ROW(할일표[날짜])-피벗!$T$11),4))),"")} | V21: {=IFERROR(IF(COUNTIFS(할일표[날짜],V$17,할일표[업무],"<>")<4,"",INDEX(구분표[아이콘],MATCH(INDEX(할일표[구분],SMALL(IF((할일표[날짜]=V$17)*(할일표[업무]<>""),ROW(할일표[구분])-ROW(INDEX(할일표[구분],1))+1),4)),구분표[구분],0))),"")} | W21: {=IFERROR(IF(COUNTIFS(할일표[날짜],V$17,할일표[업무],"<>")<4,"",INDEX(할일표[표시],SMALL(IF((할일표[날짜]=V$17)*(할일표[업무]<>""),ROW(할일표[표시])-ROW(INDEX(할일표[표시],1))+1),4))),"")} | X21: {=IFERROR(IF(COUNTIFS(할일표[날짜],V$17,할일표[업무],"<>")<4,"",INDEX(할일표[업무],SMALL(IF((할일표[날짜]=V$17)*(할일표[업무]<>""),ROW(할일표[날짜])-피벗!$T$11),4))),"")} | Y21: {=IFERROR(IF(COUNTIFS(할일표[날짜],V$17,할일표[업무],"<>")<4,"",INDEX(할일표[진행률],SMALL(IF((할일표[날짜]=V$17)*(할일표[업무]<>""),ROW(할일표[날짜])-피벗!$T$11),4))),"")} | Z21: {=IFERROR(IF(COUNTIFS(할일표[날짜],Z$17,할일표[업무],"<>")<4,"",INDEX(구분표[아이콘],MATCH(INDEX(할일표[구분],SMALL(IF((할일표[날짜]=Z$17)*(할일표[업무]<>""),ROW(할일표[구분])-ROW(INDEX(할일표[구분],1))+1),4)),구분표[구분],0))),"")} | AA21: {=IFERROR(IF(COUNTIFS(할일표[날짜],Z$17,할일표[업무],"<>")<4,"",INDEX(할일표[표시],SMALL(IF((할일표[날짜]=Z$17)*(할일표[업무]<>""),ROW(할일표[표시])-ROW(INDEX(할일표[표시],1))+1),4))),"")} | AB21: {=IFERROR(IF(COUNTIFS(할일표[날짜],Z$17,할일표[업무],"<>")<4,"",INDEX(할일표[업무],SMALL(IF((할일표[날짜]=Z$17)*(할일표[업무]<>""),ROW(할일표[날짜])-피벗!$T$11),4))),"")} | AC21: {=IFERROR(IF(COUNTIFS(할일표[날짜],Z$17,할일표[업무],"<>")<4,"",INDEX(할일표[진행률],SMALL(IF((할일표[날짜]=Z$17)*(할일표[업무]<>""),ROW(할일표[날짜])-피벗!$T$11),4))),"")}
